Workbook
Name AgData: Agenda!$A$5:$A$3004
Name AgPac: Agenda!$D$5:$D$3004
Name AgStatus: Agenda!$F$5:$F$3004
Name Convenios: Config!$K$5:$K$14
Name DiasConf: Config!$C$6
Name Formas: Config!$M$5:$M$14
Name Hoje: Config!$C$5
Name JanelaRet: Config!$C$7
Name MesAn: Config!$C$9
Name Origens: Config!$B$26:$B$31
Name PacCod: Pacientes!$A$5:$A$1004
Name PacConv: Pacientes!$D$5:$D$1004
Name PacNome: Pacientes!$B$5:$B$1004
Name PacTel: Pacientes!$C$5:$C$1004
Name ProcNome: Config!$G$5:$G$34
Name ProcRet: Config!$I$5:$I$34
Name ProcValor: Config!$H$5:$H$34
Name ProfLista: Config!$E$5:$E$14
Name StatusAg: Config!$B$18:$B$23

Sheet Início
A1: Agenda, Faltas e Retornos
A2: Carvex XLS · Menos horários vazios, mais retornos agendados
B4: ESTE É O ARQUIVO DE EXEMPLO: todos os dados são fictícios. Use-o para entender como a planilha funciona e comece a sua pela PLANILHA-LIMPA.xlsx.
B6: O que esta planilha faz
B7: Registre a agenda com status de cada atendimento. A planilha calcula a taxa de falta por profissional e dia da semana, a receita perdida com faltas, lista quem precisa ser confirmado e quais pacientes devem retornar e ainda não têm retorno agendado. Sem dados clínicos: só o necessário para a gestão.
B9: Como começar (5 minutos)
B10: 1. Config | C10: Cadastre profissionais, procedimentos (valor e dias para retorno), convênios e formas de pagamento.
B11: 2. Cadastre os pacientes | C11: Em Pacientes: código, nome, telefone e convênio. NÃO registre diagnósticos, exames ou informações de saúde.
B12: 3. Lance a agenda | C12: Em Agenda: data, hora, profissional, código do paciente, procedimento e status. Atualize o status ao longo do dia.
B13: 4. Confirme e recupere | C13: Na aba Pendências veja quem confirmar nos próximos dias e quem precisa de retorno agendado.
B14: 5. Meça os resultados | C14: Na aba Relatórios veja taxa de falta, receita perdida e receita por profissional.
B16: Mapa das abas (clique para ir)
B17: Config | C17: Profissionais, procedimentos, convênios, janelas de alerta.
B18: Pacientes | C18: Cadastro mínimo e histórico de presença.
B19: Agenda | C19: Todos os agendamentos (até 3.000 linhas).
B20: Pendências | C20: Confirmações e retornos a agendar, com telefone.
B21: Relatórios | C21: Indicadores do mês, por profissional, por dia da semana e tendência mensal.
B23: Legenda de cores
B24: Amarelo | C24: Célula que VOCÊ preenche.
B25: Cinza | C25: Cálculo automático. Não digite aqui.
B26: Verde escuro | C26: Cabeçalho de coluna.
B28: Atenção
B29: • Privacidade: use apenas dados de identificação e contato necessários para o agendamento (LGPD). Nunca lance informações de saúde.
B30: • Status 'Cancelado' e 'Remarcado' não contam como falta. 'Faltou' é a ausência sem aviso.
B31: • O valor padrão vem da tabela de procedimentos. Para convênio ou desconto, digite o valor cobrado na coluna própria.
B33: Carvex XLS · Agenda, Faltas e Retornos para Clínicas · versão 1.0 · Dúvidas: consulte o TUTORIAL.md e o MANUAL.md que acompanham o produto.

Sheet Config
A1: Configurações
A2: Preencha as células amarelas. | L2: EXEMPLO - dados fictícios
B4: Clínica | C4: Clínica Exemplo | E4: Profissionais | G4: Procedimento | H4: Valor (R$) | I4: Dias p/ retorno | K4: Convênios | M4: Formas de pagamento
B5: Data de hoje (referência) | C5: 46303 | E5: Profissional A | G5: Consulta inicial | H5: 250 | I5: 0 | K5: Particular | M5: Pix
B6: Confirmar agendamentos com até (dias) | C6: 2 | E6: Profissional B | G6: Retorno | H6: 150 | I6: 0 | K6: Convênio A | M6: Dinheiro
B7: Alertar retornos que vencem em (dias) | C7: 15 | E7: Profissional C | G7: Limpeza / manutenção | H7: 180 | I7: 180 | K7: Convênio B | M7: Cartão de débito
B8: Mês de análise (1º dia; opcional) | C8: 46266 | E8: Profissional D | G8: Avaliação | H8: 120 | I8: 30 | M8: Cartão de crédito
B9: Mês de análise efetivo | C9: =IF(ISNUMBER($C$8),DATE(YEAR($C$8),MONTH($C$8),1),DATE(YEAR(Hoje),MONTH(Hoje),1)) -> 46266 | G9: Procedimento A | H9: 350 | I9: 15 | M9: Transferência
B10: Deixe o mês vazio para analisar o mês atual. | G10: Sessão | H10: 140 | I10: 7
G11: Exame complementar | H11: 90 | I11: 0
G12: Revisão | H12: 130 | I12: 90
B17: Status do agendamento (fixos)
B18: Agendado
B19: Confirmado
B20: Compareceu
B21: Faltou
B22: Cancelado
B23: Remarcado
B25: Origem do paciente
B26: Indicação
B27: Instagram
B28: Google
B29: Convênio
B30: Passante

Sheet Pacientes
A1: Pacientes (cadastro mínimo)
A2: Somente identificação e contato. Sem informações de saúde. | J2: EXEMPLO - dados fictícios
A4: Código | B4: Nome | C4: Telefone | D4: Convênio | E4: Origem | F4: Cadastro em | G4: Observação administrativa | H4: Consultas realizadas | I4: Faltas | J4: Última visita
A5: P001 | B5: Paciente 001 | C5: (00) 94565-4237 | D5: Particular | E5: Instagram | F5: 46120 | H5: =IF($A5="","",COUNTIFS(AgPac,$A5,AgStatus,"Compareceu")) -> 7 | I5: =IF($A5="","",COUNTIFS(AgPac,$A5,AgStatus,"Faltou")) -> 0 | J5: =IF($A5="","",SUMPRODUCT(MAX((AgPac=$A5)*(AgStatus="Compareceu")*AgData))) -> 46287
A6: P002 | B6: Paciente 002 | C6: (00) 98326-2369 | D6: Convênio A | E6: Instagram | F6: 46050 | H6: =IF($A6="","",COUNTIFS(AgPac,$A6,AgStatus,"Compareceu")) -> 9 | I6: =IF($A6="","",COUNTIFS(AgPac,$A6,AgStatus,"Faltou")) -> 0 | J6: =IF($A6="","",SUMPRODUCT(MAX((AgPac=$A6)*(AgStatus="Compareceu")*AgData))) -> 46302
A7: P003 | B7: Paciente 003 | C7: (00) 96541-2745 | D7: Particular | E7: Passante | F7: 46072 | H7: =IF($A7="","",COUNTIFS(AgPac,$A7,AgStatus,"Compareceu")) -> 5 | I7: =IF($A7="","",COUNTIFS(AgPac,$A7,AgStatus,"Faltou")) -> 1 | J7: =IF($A7="","",SUMPRODUCT(MAX((AgPac=$A7)*(AgStatus="Compareceu")*AgData))) -> 46276
A8: P004 | B8: Paciente 004 | C8: (00) 95473-1684 | D8: Particular | E8: Google | F8: 46115 | H8: =IF($A8="","",COUNTIFS(AgPac,$A8,AgStatus,"Compareceu")) -> 3 | I8: =IF($A8="","",COUNTIFS(AgPac,$A8,AgStatus,"Faltou")) -> 1 | J8: =IF($A8="","",SUMPRODUCT(MAX((AgPac=$A8)*(AgStatus="Compareceu")*AgData))) -> 46281
A9: P005 | B9: Paciente 005 | C9: (00) 96105-4571 | D9: Particular | E9: Passante | F9: 46176 | H9: =IF($A9="","",COUNTIFS(AgPac,$A9,AgStatus,"Compareceu")) -> 2 | I9: =IF($A9="","",COUNTIFS(AgPac,$A9,AgStatus,"Faltou")) -> 0 | J9: =IF($A9="","",SUMPRODUCT(MAX((AgPac=$A9)*(AgStatus="Compareceu")*AgData))) -> 46300
A10: P006 | B10: Paciente 006 | C10: (00) 98534-6801 | D10: Convênio B | E10: Indicação | F10: 46147 | H10: =IF($A10="","",COUNTIFS(AgPac,$A10,AgStatus,"Compareceu")) -> 4 | I10: =IF($A10="","",COUNTIFS(AgPac,$A10,AgStatus,"Faltou")) -> 0 | J10: =IF($A10="","",SUMPRODUCT(MAX((AgPac=$A10)*(AgStatus="Compareceu")*AgData))) -> 46273
A11: P007 | B11: Paciente 007 | C11: (00) 93255-1189 | D11: Particular | E11: Instagram | F11: 46227 | H11: =IF($A11="","",COUNTIFS(AgPac,$A11,AgStatus,"Compareceu")) -> 6 | I11: =IF($A11="","",COUNTIFS(AgPac,$A11,AgStatus,"Faltou")) -> 2 | J11: =IF($A11="","",SUMPRODUCT(MAX((AgPac=$A11)*(AgStatus="Compareceu")*AgData))) -> 46294
A12: P008 | B12: Paciente 008 | C12: (00) 93219-8421 | D12: Particular | E12: Indicação | F12: 46199 | H12: =IF($A12="","",COUNTIFS(AgPac,$A12,AgStatus,"Compareceu")) -> 6 | I12: =IF($A12="","",COUNTIFS(AgPac,$A12,AgStatus,"Faltou")) -> 1 | J12: =IF($A12="","",SUMPRODUCT(MAX((AgPac=$A12)*(AgStatus="Compareceu")*AgData))) -> 46290
A13: P009 | B13: Paciente 009 | C13: (00) 91510-3710 | D13: Convênio A | E13: Instagram | F13: 46126 | H13: =IF($A13="","",COUNTIFS(AgPac,$A13,AgStatus,"Compareceu")) -> 4 | I13: =IF($A13="","",COUNTIFS(AgPac,$A13,AgStatus,"Faltou")) -> 1 | J13: =IF($A13="","",SUMPRODUCT(MAX((AgPac=$A13)*(AgStatus="Compareceu")*AgData))) -> 46298
A14: P010 | B14: Paciente 010 | C14: (00) 96475-3660 | D14: Particular | E14: Passante | F14: 46200 | H14: =IF($A14="","",COUNTIFS(AgPac,$A14,AgStatus,"Compareceu")) -> 8 | I14: =IF($A14="","",COUNTIFS(AgPac,$A14,AgStatus,"Faltou")) -> 0 | J14: =IF($A14="","",SUMPRODUCT(MAX((AgPac=$A14)*(AgStatus="Compareceu")*AgData))) -> 46273
A15: P011 | B15: Paciente 011 | C15: (00) 99378-4760 | D15: Convênio A | E15: Google | F15: 46066 | H15: =IF($A15="","",COUNTIFS(AgPac,$A15,AgStatus,"Compareceu")) -> 5 | I15: =IF($A15="","",COUNTIFS(AgPac,$A15,AgStatus,"Faltou")) -> 1 | J15: =IF($A15="","",SUMPRODUCT(MAX((AgPac=$A15)*(AgStatus="Compareceu")*AgData))) -> 46267
A16: P012 | B16: Paciente 012 | C16: (00) 98943-8585 | D16: Particular | E16: Convênio | F16: 46179 | H16: =IF($A16="","",COUNTIFS(AgPac,$A16,AgStatus,"Compareceu")) -> 5 | I16: =IF($A16="","",COUNTIFS(AgPac,$A16,AgStatus,"Faltou")) -> 0 | J16: =IF($A16="","",SUMPRODUCT(MAX((AgPac=$A16)*(AgStatus="Compareceu")*AgData))) -> 46296
... A50: P046 | B50: Paciente 046 | C50: (00) 97564-5133 | D50: Convênio A | E50: Instagram | F50: 46051 | H50: =IF($A50="","",COUNTIFS(AgPac,$A50,AgStatus,"Compareceu")) -> 4 | I50: =IF($A50="","",COUNTIFS(AgPac,$A50,AgStatus,"Faltou")) -> 1 | J50: =IF($A50="","",SUMPRODUCT(MAX((AgPac=$A50)*(AgStatus="Compareceu")*AgData))) -> 46294
H51: =IF($A51="","",COUNTIFS(AgPac,$A51,AgStatus,"Compareceu")) -> 0 | I51: =IF($A51="","",COUNTIFS(AgPac,$A51,AgStatus,"Faltou")) -> 0 | J51: =IF($A51="","",SUMPRODUCT(MAX((AgPac=$A51)*(AgStatus="Compareceu")*AgData))) -> 0
H52: =IF($A52="","",COUNTIFS(AgPac,$A52,AgStatus,"Compareceu")) -> 0 | I52: =IF($A52="","",COUNTIFS(AgPac,$A52,AgStatus,"Faltou")) -> 0 | J52: =IF($A52="","",SUMPRODUCT(MAX((AgPac=$A52)*(AgStatus="Compareceu")*AgData))) -> 0
H53: =IF($A53="","",COUNTIFS(AgPac,$A53,AgStatus,"Compareceu")) -> 0 | I53: =IF($A53="","",COUNTIFS(AgPac,$A53,AgStatus,"Faltou")) -> 0 | J53: =IF($A53="","",SUMPRODUCT(MAX((AgPac=$A53)*(AgStatus="Compareceu")*AgData))) -> 0
H54: =IF($A54="","",COUNTIFS(AgPac,$A54,AgStatus,"Compareceu")) -> 0 | I54: =IF($A54="","",COUNTIFS(AgPac,$A54,AgStatus,"Faltou")) -> 0 | J54: =IF($A54="","",SUMPRODUCT(MAX((AgPac=$A54)*(AgStatus="Compareceu")*AgData))) -> 0
H55: =IF($A55="","",COUNTIFS(AgPac,$A55,AgStatus,"Compareceu")) -> 0 | I55: =IF($A55="","",COUNTIFS(AgPac,$A55,AgStatus,"Faltou")) -> 0 | J55: =IF($A55="","",SUMPRODUCT(MAX((AgPac=$A55)*(AgStatus="Compareceu")*AgData))) -> 0
H56: =IF($A56="","",COUNTIFS(AgPac,$A56,AgStatus,"Compareceu")) -> 0 | I56: =IF($A56="","",COUNTIFS(AgPac,$A56,AgStatus,"Faltou")) -> 0 | J56: =IF($A56="","",SUMPRODUCT(MAX((AgPac=$A56)*(AgStatus="Compareceu")*AgData))) -> 0
H57: =IF($A57="","",COUNTIFS(AgPac,$A57,AgStatus,"Compareceu")) -> 0 | I57: =IF($A57="","",COUNTIFS(AgPac,$A57,AgStatus,"Faltou")) -> 0 | J57: =IF($A57="","",SUMPRODUCT(MAX((AgPac=$A57)*(AgStatus="Compareceu")*AgData))) -> 0
H58: =IF($A58="","",COUNTIFS(AgPac,$A58,AgStatus,"Compareceu")) -> 0 | I58: =IF($A58="","",COUNTIFS(AgPac,$A58,AgStatus,"Faltou")) -> 0 | J58: =IF($A58="","",SUMPRODUCT(MAX((AgPac=$A58)*(AgStatus="Compareceu")*AgData))) -> 0
H59: =IF($A59="","",COUNTIFS(AgPac,$A59,AgStatus,"Compareceu")) -> 0 | I59: =IF($A59="","",COUNTIFS(AgPac,$A59,AgStatus,"Faltou")) -> 0 | J59: =IF($A59="","",SUMPRODUCT(MAX((AgPac=$A59)*(AgStatus="Compareceu")*AgData))) -> 0
H60: =IF($A60="","",COUNTIFS(AgPac,$A60,AgStatus,"Compareceu")) -> 0 | I60: =IF($A60="","",COUNTIFS(AgPac,$A60,AgStatus,"Faltou")) -> 0 | J60: =IF($A60="","",SUMPRODUCT(MAX((AgPac=$A60)*(AgStatus="Compareceu")*AgData))) -> 0
H61: =IF($A61="","",COUNTIFS(AgPac,$A61,AgStatus,"Compareceu")) -> 0 | I61: =IF($A61="","",COUNTIFS(AgPac,$A61,AgStatus,"Faltou")) -> 0 | J61: =IF($A61="","",SUMPRODUCT(MAX((AgPac=$A61)*(AgStatus="Compareceu")*AgData))) -> 0
H62: =IF($A62="","",COUNTIFS(AgPac,$A62,AgStatus,"Compareceu")) -> 0 | I62: =IF($A62="","",COUNTIFS(AgPac,$A62,AgStatus,"Faltou")) -> 0 | J62: =IF($A62="","",SUMPRODUCT(MAX((AgPac=$A62)*(AgStatus="Compareceu")*AgData))) -> 0
... H1004: =IF($A1004="","",COUNTIFS(AgPac,$A1004,AgStatus,"Compareceu")) -> 0 | I1004: =IF($A1004="","",COUNTIFS(AgPac,$A1004,AgStatus,"Faltou")) -> 0 | J1004: =IF($A1004="","",SUMPRODUCT(MAX((AgPac=$A1004)*(AgStatus="Compareceu")*AgData))) -> 0

Sheet Agenda
A1: Agenda
A2: Uma linha por agendamento. Atualize o status ao longo do dia. | V2: EXEMPLO - dados fictícios
A4: Data | B4: Hora | C4: Profissional | D4: Cód. paciente | E4: Procedimento | F4: Status | G4: Valor cobrado (se diferente da tabela) | H4: Valor recebido (R$) | I4: Forma de pagamento | J4: Paciente | K4: Convênio | L4: Dia | M4: Valor do atendimento | N4: Receita realizada | O4: Receita perdida (falta) | P4: A receber | Q4: Retorno previsto | R4: Retorno agendado? | S4: ALERTA | T4: Mês
A5: 46204 | B5: 0.4375 | C5: Profissional A | D5: P027 | E5: Revisão | F5: Compareceu | H5: 130 | I5: Dinheiro | J5: =IF($D5="","",IFERROR(INDEX(PacNome,MATCH($D5,PacCod,0)),"Paciente não cadastrado")) -> Paciente 027 | K5: =IF($D5="","",IFERROR(INDEX(PacConv,MATCH($D5,PacCod,0))&"","")) -> Particular | L5: =IF($A5="","",CHOOSE(WEEKDAY($A5,2),"Seg","Ter","Qua","Qui","Sex","Sáb","Dom")) -> Qua | M5: =IF($E5="","",IF($G5<>"",$G5,IFERROR(INDEX(ProcValor,MATCH($E5,ProcNome,0)),0))) -> 130 | N5: =IF($M5="","",IF($F5="Compareceu",$M5,0)) -> 130 | O5: =IF($M5="","",IF($F5="Faltou",$M5,0)) -> 0 | P5: =IF($M5="","",IF($F5="Compareceu",MAX(0,$M5-N($H5)),0)) -> 0 | Q5: =IF(AND($F5="Compareceu",$E5<>"",$A5<>""),IF(IFERROR(INDEX(ProcRet,MATCH($E5,ProcNome,0)),0)>0,$A5+INDEX(ProcRet,MATCH($E5,ProcNome,0)),""),"") -> 46294 | R5: =IF($Q5="","",IF(COUNTIFS(AgPac,$D5,AgData,">"&$A5,AgStatus,"<>Cancelado",AgStatus,"<>Remarcado")>0,"Sim","Não")) -> Sim | S5: =IF($A5="","",IF(AND($F5="Agendado",$A5-Hoje>=0,$A5-Hoje<=DiasConf),"CONFIRMAR",IF(AND($A5<Hoje,OR($F5="Agendado",$F5="Confirmado")),"Atualizar status",IF(AND($F5="Compareceu",$P5>0.005),"Cobrar",IF($F5="Faltou","Falta: reagendar",""))))) -> 0 | T5: =IF($A5="","",DATE(YEAR($A5),MONTH($A5),1)) -> 46204 | U5: =IF($S5="CONFIRMAR",MAX($U$4:$U4)+1,"") -> 0 | V5: =IF(AND($R5="Não",$Q5<>"",$Q5<=Hoje+JanelaRet,$Q5>=Hoje-60),MAX($V$4:$V4)+1,"") -> 0
A6: 46204 | B6: 0.52083333 | C6: Profissional A | D6: P043 | E6: Revisão | F6: Cancelado | J6: =IF($D6="","",IFERROR(INDEX(PacNome,MATCH($D6,PacCod,0)),"Paciente não cadastrado")) -> Paciente 043 | K6: =IF($D6="","",IFERROR(INDEX(PacConv,MATCH($D6,PacCod,0))&"","")) -> Convênio A | L6: =IF($A6="","",CHOOSE(WEEKDAY($A6,2),"Seg","Ter","Qua","Qui","Sex","Sáb","Dom")) -> Qua | M6: =IF($E6="","",IF($G6<>"",$G6,IFERROR(INDEX(ProcValor,MATCH($E6,ProcNome,0)),0))) -> 130 | N6: =IF($M6="","",IF($F6="Compareceu",$M6,0)) -> 0 | O6: =IF($M6="","",IF($F6="Faltou",$M6,0)) -> 0 | P6: =IF($M6="","",IF($F6="Compareceu",MAX(0,$M6-N($H6)),0)) -> 0 | Q6: =IF(AND($F6="Compareceu",$E6<>"",$A6<>""),IF(IFERROR(INDEX(ProcRet,MATCH($E6,ProcNome,0)),0)>0,$A6+INDEX(ProcRet,MATCH($E6,ProcNome,0)),""),"") -> 0 | R6: =IF($Q6="","",IF(COUNTIFS(AgPac,$D6,AgData,">"&$A6,AgStatus,"<>Cancelado",AgStatus,"<>Remarcado")>0,"Sim","Não")) -> 0 | S6: =IF($A6="","",IF(AND($F6="Agendado",$A6-Hoje>=0,$A6-Hoje<=DiasConf),"CONFIRMAR",IF(AND($A6<Hoje,OR($F6="Agendado",$F6="Confirmado")),"Atualizar status",IF(AND($F6="Compareceu",$P6>0.005),"Cobrar",IF($F6="Faltou","Falta: reagendar",""))))) -> 0 | T6: =IF($A6="","",DATE(YEAR($A6),MONTH($A6),1)) -> 46204 | U6: =IF($S6="CONFIRMAR",MAX($U$4:$U5)+1,"") -> 0 | V6: =IF(AND($R6="Não",$Q6<>"",$Q6<=Hoje+JanelaRet,$Q6>=Hoje-60),MAX($V$4:$V5)+1,"") -> 0
A7: 46204 | B7: 0.58333333 | C7: Profissional B | D7: P032 | E7: Sessão | F7: Faltou | J7: =IF($D7="","",IFERROR(INDEX(PacNome,MATCH($D7,PacCod,0)),"Paciente não cadastrado")) -> Paciente 032 | K7: =IF($D7="","",IFERROR(INDEX(PacConv,MATCH($D7,PacCod,0))&"","")) -> Convênio A | L7: =IF($A7="","",CHOOSE(WEEKDAY($A7,2),"Seg","Ter","Qua","Qui","Sex","Sáb","Dom")) -> Qua | M7: =IF($E7="","",IF($G7<>"",$G7,IFERROR(INDEX(ProcValor,MATCH($E7,ProcNome,0)),0))) -> 140 | N7: =IF($M7="","",IF($F7="Compareceu",$M7,0)) -> 0 | O7: =IF($M7="","",IF($F7="Faltou",$M7,0)) -> 140 | P7: =IF($M7="","",IF($F7="Compareceu",MAX(0,$M7-N($H7)),0)) -> 0 | Q7: =IF(AND($F7="Compareceu",$E7<>"",$A7<>""),IF(IFERROR(INDEX(ProcRet,MATCH($E7,ProcNome,0)),0)>0,$A7+INDEX(ProcRet,MATCH($E7,ProcNome,0)),""),"") -> 0 | R7: =IF($Q7="","",IF(COUNTIFS(AgPac,$D7,AgData,">"&$A7,AgStatus,"<>Cancelado",AgStatus,"<>Remarcado")>0,"Sim","Não")) -> 0 | S7: =IF($A7="","",IF(AND($F7="Agendado",$A7-Hoje>=0,$A7-Hoje<=DiasConf),"CONFIRMAR",IF(AND($A7<Hoje,OR($F7="Agendado",$F7="Confirmado")),"Atualizar status",IF(AND($F7="Compareceu",$P7>0.005),"Cobrar",IF($F7="Faltou","Falta: reagendar",""))))) -> Falta: reagendar | T7: =IF($A7="","",DATE(YEAR($A7),MONTH($A7),1)) -> 46204 | U7: =IF($S7="CONFIRMAR",MAX($U$4:$U6)+1,"") -> 0 | V7: =IF(AND($R7="Não",$Q7<>"",$Q7<=Hoje+JanelaRet,$Q7>=Hoje-60),MAX($V$4:$V6)+1,"") -> 0
A8: 46205 | B8: 0.33333333 | C8: Profissional C | D8: P037 | E8: Consulta inicial | F8: Compareceu | G8: 150 | H8: 150 | I8: Transferência | J8: =IF($D8="","",IFERROR(INDEX(PacNome,MATCH($D8,PacCod,0)),"Paciente não cadastrado")) -> Paciente 037 | K8: =IF($D8="","",IFERROR(INDEX(PacConv,MATCH($D8,PacCod,0))&"","")) -> Convênio B | L8: =IF($A8="","",CHOOSE(WEEKDAY($A8,2),"Seg","Ter","Qua","Qui","Sex","Sáb","Dom")) -> Qui | M8: =IF($E8="","",IF($G8<>"",$G8,IFERROR(INDEX(ProcValor,MATCH($E8,ProcNome,0)),0))) -> 150 | N8: =IF($M8="","",IF($F8="Compareceu",$M8,0)) -> 150 | O8: =IF($M8="","",IF($F8="Faltou",$M8,0)) -> 0 | P8: =IF($M8="","",IF($F8="Compareceu",MAX(0,$M8-N($H8)),0)) -> 0 | Q8: =IF(AND($F8="Compareceu",$E8<>"",$A8<>""),IF(IFERROR(INDEX(ProcRet,MATCH($E8,ProcNome,0)),0)>0,$A8+INDEX(ProcRet,MATCH($E8,ProcNome,0)),""),"") -> 0 | R8: =IF($Q8="","",IF(COUNTIFS(AgPac,$D8,AgData,">"&$A8,AgStatus,"<>Cancelado",AgStatus,"<>Remarcado")>0,"Sim","Não")) -> 0 | S8: =IF($A8="","",IF(AND($F8="Agendado",$A8-Hoje>=0,$A8-Hoje<=DiasConf),"CONFIRMAR",IF(AND($A8<Hoje,OR($F8="Agendado",$F8="Confirmado")),"Atualizar status",IF(AND($F8="Compareceu",$P8>0.005),"Cobrar",IF($F8="Faltou","Falta: reagendar",""))))) -> 0 | T8: =IF($A8="","",DATE(YEAR($A8),MONTH($A8),1)) -> 46204 | U8: =IF($S8="CONFIRMAR",MAX($U$4:$U7)+1,"") -> 0 | V8: =IF(AND($R8="Não",$Q8<>"",$Q8<=Hoje+JanelaRet,$Q8>=Hoje-60),MAX($V$4:$V7)+1,"") -> 0
A9: 46205 | B9: 0.41666667 | C9: Profissional C | D9: P038 | E9: Revisão | F9: Compareceu | G9: 78 | H9: 78 | I9: Dinheiro | J9: =IF($D9="","",IFERROR(INDEX(PacNome,MATCH($D9,PacCod,0)),"Paciente não cadastrado")) -> Paciente 038 | K9: =IF($D9="","",IFERROR(INDEX(PacConv,MATCH($D9,PacCod,0))&"","")) -> Convênio A | L9: =IF($A9="","",CHOOSE(WEEKDAY($A9,2),"Seg","Ter","Qua","Qui","Sex","Sáb","Dom")) -> Qui | M9: =IF($E9="","",IF($G9<>"",$G9,IFERROR(INDEX(ProcValor,MATCH($E9,ProcNome,0)),0))) -> 78 | N9: =IF($M9="","",IF($F9="Compareceu",$M9,0)) -> 78 | O9: =IF($M9="","",IF($F9="Faltou",$M9,0)) -> 0 | P9: =IF($M9="","",IF($F9="Compareceu",MAX(0,$M9-N($H9)),0)) -> 0 | Q9: =IF(AND($F9="Compareceu",$E9<>"",$A9<>""),IF(IFERROR(INDEX(ProcRet,MATCH($E9,ProcNome,0)),0)>0,$A9+INDEX(ProcRet,MATCH($E9,ProcNome,0)),""),"") -> 46295 | R9: =IF($Q9="","",IF(COUNTIFS(AgPac,$D9,AgData,">"&$A9,AgStatus,"<>Cancelado",AgStatus,"<>Remarcado")>0,"Sim","Não")) -> Sim | S9: =IF($A9="","",IF(AND($F9="Agendado",$A9-Hoje>=0,$A9-Hoje<=DiasConf),"CONFIRMAR",IF(AND($A9<Hoje,OR($F9="Agendado",$F9="Confirmado")),"Atualizar status",IF(AND($F9="Compareceu",$P9>0.005),"Cobrar",IF($F9="Faltou","Falta: reagendar",""))))) -> 0 | T9: =IF($A9="","",DATE(YEAR($A9),MONTH($A9),1)) -> 46204 | U9: =IF($S9="CONFIRMAR",MAX($U$4:$U8)+1,"") -> 0 | V9: =IF(AND($R9="Não",$Q9<>"",$Q9<=Hoje+JanelaRet,$Q9>=Hoje-60),MAX($V$4:$V8)+1,"") -> 0
A10: 46205 | B10: 0.6875 | C10: Profissional A | D10: P029 | E10: Avaliação | F10: Compareceu | G10: 72 | H10: 72 | I10: Transferência | J10: =IF($D10="","",IFERROR(INDEX(PacNome,MATCH($D10,PacCod,0)),"Paciente não cadastrado")) -> Paciente 029 | K10: =IF($D10="","",IFERROR(INDEX(PacConv,MATCH($D10,PacCod,0))&"","")) -> Convênio B | L10: =IF($A10="","",CHOOSE(WEEKDAY($A10,2),"Seg","Ter","Qua","Qui","Sex","Sáb","Dom")) -> Qui | M10: =IF($E10="","",IF($G10<>"",$G10,IFERROR(INDEX(ProcValor,MATCH($E10,ProcNome,0)),0))) -> 72 | N10: =IF($M10="","",IF($F10="Compareceu",$M10,0)) -> 72 | O10: =IF($M10="","",IF($F10="Faltou",$M10,0)) -> 0 | P10: =IF($M10="","",IF($F10="Compareceu",MAX(0,$M10-N($H10)),0)) -> 0 | Q10: =IF(AND($F10="Compareceu",$E10<>"",$A10<>""),IF(IFERROR(INDEX(ProcRet,MATCH($E10,ProcNome,0)),0)>0,$A10+INDEX(ProcRet,MATCH($E10,ProcNome,0)),""),"") -> 46235 | R10: =IF($Q10="","",IF(COUNTIFS(AgPac,$D10,AgData,">"&$A10,AgStatus,"<>Cancelado",AgStatus,"<>Remarcado")>0,"Sim","Não")) -> Sim | S10: =IF($A10="","",IF(AND($F10="Agendado",$A10-Hoje>=0,$A10-Hoje<=DiasConf),"CONFIRMAR",IF(AND($A10<Hoje,OR($F10="Agendado",$F10="Confirmado")),"Atualizar status",IF(AND($F10="Compareceu",$P10>0.005),"Cobrar",IF($F10="Faltou","Falta: reagendar",""))))) -> 0 | T10: =IF($A10="","",DATE(YEAR($A10),MONTH($A10),1)) -> 46204 | U10: =IF($S10="CONFIRMAR",MAX($U$4:$U9)+1,"") -> 0 | V10: =IF(AND($R10="Não",$Q10<>"",$Q10<=Hoje+JanelaRet,$Q10>=Hoje-60),MAX($V$4:$V9)+1,"") -> 0
A11: 46206 | B11: 0.35416667 | C11: Profissional B | D11: P008 | E11: Sessão | F11: Compareceu | J11: =IF($D11="","",IFERROR(INDEX(PacNome,MATCH($D11,PacCod,0)),"Paciente não cadastrado")) -> Paciente 008 | K11: =IF($D11="","",IFERROR(INDEX(PacConv,MATCH($D11,PacCod,0))&"","")) -> Particular | L11: =IF($A11="","",CHOOSE(WEEKDAY($A11,2),"Seg","Ter","Qua","Qui","Sex","Sáb","Dom")) -> Sex | M11: =IF($E11="","",IF($G11<>"",$G11,IFERROR(INDEX(ProcValor,MATCH($E11,ProcNome,0)),0))) -> 140 | N11: =IF($M11="","",IF($F11="Compareceu",$M11,0)) -> 140 | O11: =IF($M11="","",IF($F11="Faltou",$M11,0)) -> 0 | P11: =IF($M11="","",IF($F11="Compareceu",MAX(0,$M11-N($H11)),0)) -> 140 | Q11: =IF(AND($F11="Compareceu",$E11<>"",$A11<>""),IF(IFERROR(INDEX(ProcRet,MATCH($E11,ProcNome,0)),0)>0,$A11+INDEX(ProcRet,MATCH($E11,ProcNome,0)),""),"") -> 46213 | R11: =IF($Q11="","",IF(COUNTIFS(AgPac,$D11,AgData,">"&$A11,AgStatus,"<>Cancelado",AgStatus,"<>Remarcado")>0,"Sim","Não")) -> Sim | S11: =IF($A11="","",IF(AND($F11="Agendado",$A11-Hoje>=0,$A11-Hoje<=DiasConf),"CONFIRMAR",IF(AND($A11<Hoje,OR($F11="Agendado",$F11="Confirmado")),"Atualizar status",IF(AND($F11="Compareceu",$P11>0.005),"Cobrar",IF($F11="Faltou","Falta: reagendar",""))))) -> Cobrar | T11: =IF($A11="","",DATE(YEAR($A11),MONTH($A11),1)) -> 46204 | U11: =IF($S11="CONFIRMAR",MAX($U$4:$U10)+1,"") -> 0 | V11: =IF(AND($R11="Não",$Q11<>"",$Q11<=Hoje+JanelaRet,$Q11>=Hoje-60),MAX($V$4:$V10)+1,"") -> 0
A12: 46206 | B12: 0.41666667 | C12: Profissional D | D12: P002 | E12: Revisão | F12: Compareceu | G12: 78 | H12: 78 | I12: Pix | J12: =IF($D12="","",IFERROR(INDEX(PacNome,MATCH($D12,PacCod,0)),"Paciente não cadastrado")) -> Paciente 002 | K12: =IF($D12="","",IFERROR(INDEX(PacConv,MATCH($D12,PacCod,0))&"","")) -> Convênio A | L12: =IF($A12="","",CHOOSE(WEEKDAY($A12,2),"Seg","Ter","Qua","Qui","Sex","Sáb","Dom")) -> Sex | M12: =IF($E12="","",IF($G12<>"",$G12,IFERROR(INDEX(ProcValor,MATCH($E12,ProcNome,0)),0))) -> 78 | N12: =IF($M12="","",IF($F12="Compareceu",$M12,0)) -> 78 | O12: =IF($M12="","",IF($F12="Faltou",$M12,0)) -> 0 | P12: =IF($M12="","",IF($F12="Compareceu",MAX(0,$M12-N($H12)),0)) -> 0 | Q12: =IF(AND($F12="Compareceu",$E12<>"",$A12<>""),IF(IFERROR(INDEX(ProcRet,MATCH($E12,ProcNome,0)),0)>0,$A12+INDEX(ProcRet,MATCH($E12,ProcNome,0)),""),"") -> 46296 | R12: =IF($Q12="","",IF(COUNTIFS(AgPac,$D12,AgData,">"&$A12,AgStatus,"<>Cancelado",AgStatus,"<>Remarcado")>0,"Sim","Não")) -> Sim | S12: =IF($A12="","",IF(AND($F12="Agendado",$A12-Hoje>=0,$A12-Hoje<=DiasConf),"CONFIRMAR",IF(AND($A12<Hoje,OR($F12="Agendado",$F12="Confirmado")),"Atualizar status",IF(AND($F12="Compareceu",$P12>0.005),"Cobrar",IF($F12="Faltou","Falta: reagendar",""))))) -> 0 | T12: =IF($A12="","",DATE(YEAR($A12),MONTH($A12),1)) -> 46204 | U12: =IF($S12="CONFIRMAR",MAX($U$4:$U11)+1,"") -> 0 | V12: =IF(AND($R12="Não",$Q12<>"",$Q12<=Hoje+JanelaRet,$Q12>=Hoje-60),MAX($V$4:$V11)+1,"") -> 0
A13: 46206 | B13: 0.60416667 | C13: Profissional C | D13: P019 | E13: Sessão | F13: Compareceu | H13: 140 | I13: Cartão de débito | J13: =IF($D13="","",IFERROR(INDEX(PacNome,MATCH($D13,PacCod,0)),"Paciente não cadastrado")) -> Paciente 019 | K13: =IF($D13="","",IFERROR(INDEX(PacConv,MATCH($D13,PacCod,0))&"","")) -> Particular | L13: =IF($A13="","",CHOOSE(WEEKDAY($A13,2),"Seg","Ter","Qua","Qui","Sex","Sáb","Dom")) -> Sex | M13: =IF($E13="","",IF($G13<>"",$G13,IFERROR(INDEX(ProcValor,MATCH($E13,ProcNome,0)),0))) -> 140 | N13: =IF($M13="","",IF($F13="Compareceu",$M13,0)) -> 140 | O13: =IF($M13="","",IF($F13="Faltou",$M13,0)) -> 0 | P13: =IF($M13="","",IF($F13="Compareceu",MAX(0,$M13-N($H13)),0)) -> 0 | Q13: =IF(AND($F13="Compareceu",$E13<>"",$A13<>""),IF(IFERROR(INDEX(ProcRet,MATCH($E13,ProcNome,0)),0)>0,$A13+INDEX(ProcRet,MATCH($E13,ProcNome,0)),""),"") -> 46213 | R13: =IF($Q13="","",IF(COUNTIFS(AgPac,$D13,AgData,">"&$A13,AgStatus,"<>Cancelado",AgStatus,"<>Remarcado")>0,"Sim","Não")) -> Sim | S13: =IF($A13="","",IF(AND($F13="Agendado",$A13-Hoje>=0,$A13-Hoje<=DiasConf),"CONFIRMAR",IF(AND($A13<Hoje,OR($F13="Agendado",$F13="Confirmado")),"Atualizar status",IF(AND($F13="Compareceu",$P13>0.005),"Cobrar",IF($F13="Faltou","Falta: reagendar",""))))) -> 0 | T13: =IF($A13="","",DATE(YEAR($A13),MONTH($A13),1)) -> 46204 | U13: =IF($S13="CONFIRMAR",MAX($U$4:$U12)+1,"") -> 0 | V13: =IF(AND($R13="Não",$Q13<>"",$Q13<=Hoje+JanelaRet,$Q13>=Hoje-60),MAX($V$4:$V12)+1,"") -> 0
A14: 46206 | B14: 0.6875 | C14: Profissional A | D14: P011 | E14: Sessão | F14: Compareceu | G14: 84 | H14: 84 | I14: Cartão de crédito | J14: =IF($D14="","",IFERROR(INDEX(PacNome,MATCH($D14,PacCod,0)),"Paciente não cadastrado")) -> Paciente 011 | K14: =IF($D14="","",IFERROR(INDEX(PacConv,MATCH($D14,PacCod,0))&"","")) -> Convênio A | L14: =IF($A14="","",CHOOSE(WEEKDAY($A14,2),"Seg","Ter","Qua","Qui","Sex","Sáb","Dom")) -> Sex | M14: =IF($E14="","",IF($G14<>"",$G14,IFERROR(INDEX(ProcValor,MATCH($E14,ProcNome,0)),0))) -> 84 | N14: =IF($M14="","",IF($F14="Compareceu",$M14,0)) -> 84 | O14: =IF($M14="","",IF($F14="Faltou",$M14,0)) -> 0 | P14: =IF($M14="","",IF($F14="Compareceu",MAX(0,$M14-N($H14)),0)) -> 0 | Q14: =IF(AND($F14="Compareceu",$E14<>"",$A14<>""),IF(IFERROR(INDEX(ProcRet,MATCH($E14,ProcNome,0)),0)>0,$A14+INDEX(ProcRet,MATCH($E14,ProcNome,0)),""),"") -> 46213 | R14: =IF($Q14="","",IF(COUNTIFS(AgPac,$D14,AgData,">"&$A14,AgStatus,"<>Cancelado",AgStatus,"<>Remarcado")>0,"Sim","Não")) -> Sim | S14: =IF($A14="","",IF(AND($F14="Agendado",$A14-Hoje>=0,$A14-Hoje<=DiasConf),"CONFIRMAR",IF(AND($A14<Hoje,OR($F14="Agendado",$F14="Confirmado")),"Atualizar status",IF(AND($F14="Compareceu",$P14>0.005),"Cobrar",IF($F14="Faltou","Falta: reagendar",""))))) -> 0 | T14: =IF($A14="","",DATE(YEAR($A14),MONTH($A14),1)) -> 46204 | U14: =IF($S14="CONFIRMAR",MAX($U$4:$U13)+1,"") -> 0 | V14: =IF(AND($R14="Não",$Q14<>"",$Q14<=Hoje+JanelaRet,$Q14>=Hoje-60),MAX($V$4:$V13)+1,"") -> 0
A15: 46207 | B15: 0.41666667 | C15: Profissional C | D15: P018 | E15: Sessão | F15: Faltou | J15: =IF($D15="","",IFERROR(INDEX(PacNome,MATCH($D15,PacCod,0)),"Paciente não cadastrado")) -> Paciente 018 | K15: =IF($D15="","",IFERROR(INDEX(PacConv,MATCH($D15,PacCod,0))&"","")) -> Particular | L15: =IF($A15="","",CHOOSE(WEEKDAY($A15,2),"Seg","Ter","Qua","Qui","Sex","Sáb","Dom")) -> Sáb | M15: =IF($E15="","",IF($G15<>"",$G15,IFERROR(INDEX(ProcValor,MATCH($E15,ProcNome,0)),0))) -> 140 | N15: =IF($M15="","",IF($F15="Compareceu",$M15,0)) -> 0 | O15: =IF($M15="","",IF($F15="Faltou",$M15,0)) -> 140 | P15: =IF($M15="","",IF($F15="Compareceu",MAX(0,$M15-N($H15)),0)) -> 0 | Q15: =IF(AND($F15="Compareceu",$E15<>"",$A15<>""),IF(IFERROR(INDEX(ProcRet,MATCH($E15,ProcNome,0)),0)>0,$A15+INDEX(ProcRet,MATCH($E15,ProcNome,0)),""),"") -> 0 | R15: =IF($Q15="","",IF(COUNTIFS(AgPac,$D15,AgData,">"&$A15,AgStatus,"<>Cancelado",AgStatus,"<>Remarcado")>0,"Sim","Não")) -> 0 | S15: =IF($A15="","",IF(AND($F15="Agendado",$A15-Hoje>=0,$A15-Hoje<=DiasConf),"CONFIRMAR",IF(AND($A15<Hoje,OR($F15="Agendado",$F15="Confirmado")),"Atualizar status",IF(AND($F15="Compareceu",$P15>0.005),"Cobrar",IF($F15="Faltou","Falta: reagendar",""))))) -> Falta: reagendar | T15: =IF($A15="","",DATE(YEAR($A15),MONTH($A15),1)) -> 46204 | U15: =IF($S15="CONFIRMAR",MAX($U$4:$U14)+1,"") -> 0 | V15: =IF(AND($R15="Não",$Q15<>"",$Q15<=Hoje+JanelaRet,$Q15>=Hoje-60),MAX($V$4:$V14)+1,"") -> 0
A16: 46207 | B16: 0.70833333 | C16: Profissional D | D16: P039 | E16: Retorno | F16: Compareceu | H16: 150 | I16: Dinheiro | J16: =IF($D16="","",IFERROR(INDEX(PacNome,MATCH($D16,PacCod,0)),"Paciente não cadastrado")) -> Paciente 039 | K16: =IF($D16="","",IFERROR(INDEX(PacConv,MATCH($D16,PacCod,0))&"","")) -> Particular | L16: =IF($A16="","",CHOOSE(WEEKDAY($A16,2),"Seg","Ter","Qua","Qui","Sex","Sáb","Dom")) -> Sáb | M16: =IF($E16="","",IF($G16<>"",$G16,IFERROR(INDEX(ProcValor,MATCH($E16,ProcNome,0)),0))) -> 150 | N16: =IF($M16="","",IF($F16="Compareceu",$M16,0)) -> 150 | O16: =IF($M16="","",IF($F16="Faltou",$M16,0)) -> 0 | P16: =IF($M16="","",IF($F16="Compareceu",MAX(0,$M16-N($H16)),0)) -> 0 | Q16: =IF(AND($F16="Compareceu",$E16<>"",$A16<>""),IF(IFERROR(INDEX(ProcRet,MATCH($E16,ProcNome,0)),0)>0,$A16+INDEX(ProcRet,MATCH($E16,ProcNome,0)),""),"") -> 0 | R16: =IF($Q16="","",IF(COUNTIFS(AgPac,$D16,AgData,">"&$A16,AgStatus,"<>Cancelado",AgStatus,"<>Remarcado")>0,"Sim","Não")) -> 0 | S16: =IF($A16="","",IF(AND($F16="Agendado",$A16-Hoje>=0,$A16-Hoje<=DiasConf),"CONFIRMAR",IF(AND($A16<Hoje,OR($F16="Agendado",$F16="Confirmado")),"Atualizar status",IF(AND($F16="Compareceu",$P16>0.005),"Cobrar",IF($F16="Faltou","Falta: reagendar",""))))) -> 0 | T16: =IF($A16="","",DATE(YEAR($A16),MONTH($A16),1)) -> 46204 | U16: =IF($S16="CONFIRMAR",MAX($U$4:$U15)+1,"") -> 0 | V16: =IF(AND($R16="Não",$Q16<>"",$Q16<=Hoje+JanelaRet,$Q16>=Hoje-60),MAX($V$4:$V15)+1,"") -> 0
A17: 46209 | B17: 0.375 | C17: Profissional C | D17: P034 | E17: Sessão | F17: Compareceu | H17: 140 | I17: Dinheiro | J17: =IF($D17="","",IFERROR(INDEX(PacNome,MATCH($D17,PacCod,0)),"Paciente não cadastrado")) -> Paciente 034 | K17: =IF($D17="","",IFERROR(INDEX(PacConv,MATCH($D17,PacCod,0))&"","")) -> Particular | L17: =IF($A17="","",CHOOSE(WEEKDAY($A17,2),"Seg","Ter","Qua","Qui","Sex","Sáb","Dom")) -> Seg | M17: =IF($E17="","",IF($G17<>"",$G17,IFERROR(INDEX(ProcValor,MATCH($E17,ProcNome,0)),0))) -> 140 | N17: =IF($M17="","",IF($F17="Compareceu",$M17,0)) -> 140 | O17: =IF($M17="","",IF($F17="Faltou",$M17,0)) -> 0 | P17: =IF($M17="","",IF($F17="Compareceu",MAX(0,$M17-N($H17)),0)) -> 0 | Q17: =IF(AND($F17="Compareceu",$E17<>"",$A17<>""),IF(IFERROR(INDEX(ProcRet,MATCH($E17,ProcNome,0)),0)>0,$A17+INDEX(ProcRet,MATCH($E17,ProcNome,0)),""),"") -> 46216 | R17: =IF($Q17="","",IF(COUNTIFS(AgPac,$D17,AgData,">"&$A17,AgStatus,"<>Cancelado",AgStatus,"<>Remarcado")>0,"Sim","Não")) -> Sim | S17: =IF($A17="","",IF(AND($F17="Agendado",$A17-Hoje>=0,$A17-Hoje<=DiasConf),"CONFIRMAR",IF(AND($A17<Hoje,OR($F17="Agendado",$F17="Confirmado")),"Atualizar status",IF(AND($F17="Compareceu",$P17>0.005),"Cobrar",IF($F17="Faltou","Falta: reagendar",""))))) -> 0 | T17: =IF($A17="","",DATE(YEAR($A17),MONTH($A17),1)) -> 46204 | U17: =IF($S17="CONFIRMAR",MAX($U$4:$U16)+1,"") -> 0 | V17: =IF(AND($R17="Não",$Q17<>"",$Q17<=Hoje+JanelaRet,$Q17>=Hoje-60),MAX($V$4:$V16)+1,"") -> 0
A18: 46209 | B18: 0.47916667 | C18: Profissional B | D18: P022 | E18: Sessão | F18: Compareceu | G18: 84 | H18: 84 | I18: Transferência | J18: =IF($D18="","",IFERROR(INDEX(PacNome,MATCH($D18,PacCod,0)),"Paciente não cadastrado")) -> Paciente 022 | K18: =IF($D18="","",IFERROR(INDEX(PacConv,MATCH($D18,PacCod,0))&"","")) -> Convênio A | L18: =IF($A18="","",CHOOSE(WEEKDAY($A18,2),"Seg","Ter","Qua","Qui","Sex","Sáb","Dom")) -> Seg | M18: =IF($E18="","",IF($G18<>"",$G18,IFERROR(INDEX(ProcValor,MATCH($E18,ProcNome,0)),0))) -> 84 | N18: =IF($M18="","",IF($F18="Compareceu",$M18,0)) -> 84 | O18: =IF($M18="","",IF($F18="Faltou",$M18,0)) -> 0 | P18: =IF($M18="","",IF($F18="Compareceu",MAX(0,$M18-N($H18)),0)) -> 0 | Q18: =IF(AND($F18="Compareceu",$E18<>"",$A18<>""),IF(IFERROR(INDEX(ProcRet,MATCH($E18,ProcNome,0)),0)>0,$A18+INDEX(ProcRet,MATCH($E18,ProcNome,0)),""),"") -> 46216 | R18: =IF($Q18="","",IF(COUNTIFS(AgPac,$D18,AgData,">"&$A18,AgStatus,"<>Cancelado",AgStatus,"<>Remarcado")>0,"Sim","Não")) -> Sim | S18: =IF($A18="","",IF(AND($F18="Agendado",$A18-Hoje>=0,$A18-Hoje<=DiasConf),"CONFIRMAR",IF(AND($A18<Hoje,OR($F18="Agendado",$F18="Confirmado")),"Atualizar status",IF(AND($F18="Compareceu",$P18>0.005),"Cobrar",IF($F18="Faltou","Falta: reagendar",""))))) -> 0 | T18: =IF($A18="","",DATE(YEAR($A18),MONTH($A18),1)) -> 46204 | U18: =IF($S18="CONFIRMAR",MAX($U$4:$U17)+1,"") -> 0 | V18: =IF(AND($R18="Não",$Q18<>"",$Q18<=Hoje+JanelaRet,$Q18>=Hoje-60),MAX($V$4:$V17)+1,"") -> 0
A19: 46209 | B19: 0.58333333 | C19: Profissional B | D19: P006 | E19: Sessão | F19: Compareceu | G19: 84 | H19: 84 | I19: Pix | J19: =IF($D19="","",IFERROR(INDEX(PacNome,MATCH($D19,PacCod,0)),"Paciente não cadastrado")) -> Paciente 006 | K19: =IF($D19="","",IFERROR(INDEX(PacConv,MATCH($D19,PacCod,0))&"","")) -> Convênio B | L19: =IF($A19="","",CHOOSE(WEEKDAY($A19,2),"Seg","Ter","Qua","Qui","Sex","Sáb","Dom")) -> Seg | M19: =IF($E19="","",IF($G19<>"",$G19,IFERROR(INDEX(ProcValor,MATCH($E19,ProcNome,0)),0))) -> 84 | N19: =IF($M19="","",IF($F19="Compareceu",$M19,0)) -> 84 | O19: =IF($M19="","",IF($F19="Faltou",$M19,0)) -> 0 | P19: =IF($M19="","",IF($F19="Compareceu",MAX(0,$M19-N($H19)),0)) -> 0 | Q19: =IF(AND($F19="Compareceu",$E19<>"",$A19<>""),IF(IFERROR(INDEX(ProcRet,MATCH($E19,ProcNome,0)),0)>0,$A19+INDEX(ProcRet,MATCH($E19,ProcNome,0)),""),"") -> 46216 | R19: =IF($Q19="","",IF(COUNTIFS(AgPac,$D19,AgData,">"&$A19,AgStatus,"<>Cancelado",AgStatus,"<>Remarcado")>0,"Sim","Não")) -> Sim | S19: =IF($A19="","",IF(AND($F19="Agendado",$A19-Hoje>=0,$A19-Hoje<=DiasConf),"CONFIRMAR",IF(AND($A19<Hoje,OR($F19="Agendado",$F19="Confirmado")),"Atualizar status",IF(AND($F19="Compareceu",$P19>0.005),"Cobrar",IF($F19="Faltou","Falta: reagendar",""))))) -> 0 | T19: =IF($A19="","",DATE(YEAR($A19),MONTH($A19),1)) -> 46204 | U19: =IF($S19="CONFIRMAR",MAX($U$4:$U18)+1,"") -> 0 | V19: =IF(AND($R19="Não",$Q19<>"",$Q19<=Hoje+JanelaRet,$Q19>=Hoje-60),MAX($V$4:$V18)+1,"") -> 0
A20: 46210 | B20: 0.4375 | C20: Profissional C | D20: P042 | E20: Exame complementar | F20: Compareceu | H20: 90 | I20: Cartão de crédito | J20: =IF($D20="","",IFERROR(INDEX(PacNome,MATCH($D20,PacCod,0)),"Paciente não cadastrado")) -> Paciente 042 | K20: =IF($D20="","",IFERROR(INDEX(PacConv,MATCH($D20,PacCod,0))&"","")) -> Particular | L20: =IF($A20="","",CHOOSE(WEEKDAY($A20,2),"Seg","Ter","Qua","Qui","Sex","Sáb","Dom")) -> Ter | M20: =IF($E20="","",IF($G20<>"",$G20,IFERROR(INDEX(ProcValor,MATCH($E20,ProcNome,0)),0))) -> 90 | N20: =IF($M20="","",IF($F20="Compareceu",$M20,0)) -> 90 | O20: =IF($M20="","",IF($F20="Faltou",$M20,0)) -> 0 | P20: =IF($M20="","",IF($F20="Compareceu",MAX(0,$M20-N($H20)),0)) -> 0 | Q20: =IF(AND($F20="Compareceu",$E20<>"",$A20<>""),IF(IFERROR(INDEX(ProcRet,MATCH($E20,ProcNome,0)),0)>0,$A20+INDEX(ProcRet,MATCH($E20,ProcNome,0)),""),"") -> 0 | R20: =IF($Q20="","",IF(COUNTIFS(AgPac,$D20,AgData,">"&$A20,AgStatus,"<>Cancelado",AgStatus,"<>Remarcado")>0,"Sim","Não")) -> 0 | S20: =IF($A20="","",IF(AND($F20="Agendado",$A20-Hoje>=0,$A20-Hoje<=DiasConf),"CONFIRMAR",IF(AND($A20<Hoje,OR($F20="Agendado",$F20="Confirmado")),"Atualizar status",IF(AND($F20="Compareceu",$P20>0.005),"Cobrar",IF($F20="Faltou","Falta: reagendar",""))))) -> 0 | T20: =IF($A20="","",DATE(YEAR($A20),MONTH($A20),1)) -> 46204 | U20: =IF($S20="CONFIRMAR",MAX($U$4:$U19)+1,"") -> 0 | V20: =IF(AND($R20="Não",$Q20<>"",$Q20<=Hoje+JanelaRet,$Q20>=Hoje-60),MAX($V$4:$V19)+1,"") -> 0
A21: 46210 | B21: 0.58333333 | C21: Profissional C | D21: P041 | E21: Avaliação | F21: Compareceu | G21: 72 | H21: 72 | I21: Pix | J21: =IF($D21="","",IFERROR(INDEX(PacNome,MATCH($D21,PacCod,0)),"Paciente não cadastrado")) -> Paciente 041 | K21: =IF($D21="","",IFERROR(INDEX(PacConv,MATCH($D21,PacCod,0))&"","")) -> Convênio B | L21: =IF($A21="","",CHOOSE(WEEKDAY($A21,2),"Seg","Ter","Qua","Qui","Sex","Sáb","Dom")) -> Ter | M21: =IF($E21="","",IF($G21<>"",$G21,IFERROR(INDEX(ProcValor,MATCH($E21,ProcNome,0)),0))) -> 72 | N21: =IF($M21="","",IF($F21="Compareceu",$M21,0)) -> 72 | O21: =IF($M21="","",IF($F21="Faltou",$M21,0)) -> 0 | P21: =IF($M21="","",IF($F21="Compareceu",MAX(0,$M21-N($H21)),0)) -> 0 | Q21: =IF(AND($F21="Compareceu",$E21<>"",$A21<>""),IF(IFERROR(INDEX(ProcRet,MATCH($E21,ProcNome,0)),0)>0,$A21+INDEX(ProcRet,MATCH($E21,ProcNome,0)),""),"") -> 46240 | R21: =IF($Q21="","",IF(COUNTIFS(AgPac,$D21,AgData,">"&$A21,AgStatus,"<>Cancelado",AgStatus,"<>Remarcado")>0,"Sim","Não")) -> Sim | S21: =IF($A21="","",IF(AND($F21="Agendado",$A21-Hoje>=0,$A21-Hoje<=DiasConf),"CONFIRMAR",IF(AND($A21<Hoje,OR($F21="Agendado",$F21="Confirmado")),"Atualizar status",IF(AND($F21="Compareceu",$P21>0.005),"Cobrar",IF($F21="Faltou","Falta: reagendar",""))))) -> 0 | T21: =IF($A21="","",DATE(YEAR($A21),MONTH($A21),1)) -> 46204 | U21: =IF($S21="CONFIRMAR",MAX($U$4:$U20)+1,"") -> 0 | V21: =IF(AND($R21="Não",$Q21<>"",$Q21<=Hoje+JanelaRet,$Q21>=Hoje-60),MAX($V$4:$V20)+1,"") -> 0
A22: 46210 | B22: 0.72916667 | C22: Profissional D | D22: P042 | E22: Revisão | F22: Compareceu | H22: 130 | I22: Cartão de crédito | J22: =IF($D22="","",IFERROR(INDEX(PacNome,MATCH($D22,PacCod,0)),"Paciente não cadastrado")) -> Paciente 042 | K22: =IF($D22="","",IFERROR(INDEX(PacConv,MATCH($D22,PacCod,0))&"","")) -> Particular | L22: =IF($A22="","",CHOOSE(WEEKDAY($A22,2),"Seg","Ter","Qua","Qui","Sex","Sáb","Dom")) -> Ter | M22: =IF($E22="","",IF($G22<>"",$G22,IFERROR(INDEX(ProcValor,MATCH($E22,ProcNome,0)),0))) -> 130 | N22: =IF($M22="","",IF($F22="Compareceu",$M22,0)) -> 130 | O22: =IF($M22="","",IF($F22="Faltou",$M22,0)) -> 0 | P22: =IF($M22="","",IF($F22="Compareceu",MAX(0,$M22-N($H22)),0)) -> 0 | Q22: =IF(AND($F22="Compareceu",$E22<>"",$A22<>""),IF(IFERROR(INDEX(ProcRet,MATCH($E22,ProcNome,0)),0)>0,$A22+INDEX(ProcRet,MATCH($E22,ProcNome,0)),""),"") -> 46300 | R22: =IF($Q22="","",IF(COUNTIFS(AgPac,$D22,AgData,">"&$A22,AgStatus,"<>Cancelado",AgStatus,"<>Remarcado")>0,"Sim","Não")) -> Sim | S22: =IF($A22="","",IF(AND($F22="Agendado",$A22-Hoje>=0,$A22-Hoje<=DiasConf),"CONFIRMAR",IF(AND($A22<Hoje,OR($F22="Agendado",$F22="Confirmado")),"Atualizar status",IF(AND($F22="Compareceu",$P22>0.005),"Cobrar",IF($F22="Faltou","Falta: reagendar",""))))) -> 0 | T22: =IF($A22="","",DATE(YEAR($A22),MONTH($A22),1)) -> 46204 | U22: =IF($S22="CONFIRMAR",MAX($U$4:$U21)+1,"") -> 0 | V22: =IF(AND($R22="Não",$Q22<>"",$Q22<=Hoje+JanelaRet,$Q22>=Hoje-60),MAX($V$4:$V21)+1,"") -> 0
A23: 46211 | B23: 0.375 | C23: Profissional B | D23: P003 | E23: Revisão | F23: Compareceu | H23: 130 | I23: Cartão de débito | J23: =IF($D23="","",IFERROR(INDEX(PacNome,MATCH($D23,PacCod,0)),"Paciente não cadastrado")) -> Paciente 003 | K23: =IF($D23="","",IFERROR(INDEX(PacConv,MATCH($D23,PacCod,0))&"","")) -> Particular | L23: =IF($A23="","",CHOOSE(WEEKDAY($A23,2),"Seg","Ter","Qua","Qui","Sex","Sáb","Dom")) -> Qua | M23: =IF($E23="","",IF($G23<>"",$G23,IFERROR(INDEX(ProcValor,MATCH($E23,ProcNome,0)),0))) -> 130 | N23: =IF($M23="","",IF($F23="Compareceu",$M23,0)) -> 130 | O23: =IF($M23="","",IF($F23="Faltou",$M23,0)) -> 0 | P23: =IF($M23="","",IF($F23="Compareceu",MAX(0,$M23-N($H23)),0)) -> 0 | Q23: =IF(AND($F23="Compareceu",$E23<>"",$A23<>""),IF(IFERROR(INDEX(ProcRet,MATCH($E23,ProcNome,0)),0)>0,$A23+INDEX(ProcRet,MATCH($E23,ProcNome,0)),""),"") -> 46301 | R23: =IF($Q23="","",IF(COUNTIFS(AgPac,$D23,AgData,">"&$A23,AgStatus,"<>Cancelado",AgStatus,"<>Remarcado")>0,"Sim","Não")) -> Sim | S23: =IF($A23="","",IF(AND($F23="Agendado",$A23-Hoje>=0,$A23-Hoje<=DiasConf),"CONFIRMAR",IF(AND($A23<Hoje,OR($F23="Agendado",$F23="Confirmado")),"Atualizar status",IF(AND($F23="Compareceu",$P23>0.005),"Cobrar",IF($F23="Faltou","Falta: reagendar",""))))) -> 0 | T23: =IF($A23="","",DATE(YEAR($A23),MONTH($A23),1)) -> 46204 | U23: =IF($S23="CONFIRMAR",MAX($U$4:$U22)+1,"") -> 0 | V23: =IF(AND($R23="Não",$Q23<>"",$Q23<=Hoje+JanelaRet,$Q23>=Hoje-60),MAX($V$4:$V22)+1,"") -> 0
A24: 46211 | B24: 0.4375 | C24: Profissional C | D24: P038 | E24: Procedimento A | F24: Compareceu | G24: 210 | H24: 210 | I24: Pix | J24: =IF($D24="","",IFERROR(INDEX(PacNome,MATCH($D24,PacCod,0)),"Paciente não cadastrado")) -> Paciente 038 | K24: =IF($D24="","",IFERROR(INDEX(PacConv,MATCH($D24,PacCod,0))&"","")) -> Convênio A | L24: =IF($A24="","",CHOOSE(WEEKDAY($A24,2),"Seg","Ter","Qua","Qui","Sex","Sáb","Dom")) -> Qua | M24: =IF($E24="","",IF($G24<>"",$G24,IFERROR(INDEX(ProcValor,MATCH($E24,ProcNome,0)),0))) -> 210 | N24: =IF($M24="","",IF($F24="Compareceu",$M24,0)) -> 210 | O24: =IF($M24="","",IF($F24="Faltou",$M24,0)) -> 0 | P24: =IF($M24="","",IF($F24="Compareceu",MAX(0,$M24-N($H24)),0)) -> 0 | Q24: =IF(AND($F24="Compareceu",$E24<>"",$A24<>""),IF(IFERROR(INDEX(ProcRet,MATCH($E24,ProcNome,0)),0)>0,$A24+INDEX(ProcRet,MATCH($E24,ProcNome,0)),""),"") -> 46226 | R24: =IF($Q24="","",IF(COUNTIFS(AgPac,$D24,AgData,">"&$A24,AgStatus,"<>Cancelado",AgStatus,"<>Remarcado")>0,"Sim","Não")) -> Sim | S24: =IF($A24="","",IF(AND($F24="Agendado",$A24-Hoje>=0,$A24-Hoje<=DiasConf),"CONFIRMAR",IF(AND($A24<Hoje,OR($F24="Agendado",$F24="Confirmado")),"Atualizar status",IF(AND($F24="Compareceu",$P24>0.005),"Cobrar",IF($F24="Faltou","Falta: reagendar",""))))) -> 0 | T24: =IF($A24="","",DATE(YEAR($A24),MONTH($A24),1)) -> 46204 | U24: =IF($S24="CONFIRMAR",MAX($U$4:$U23)+1,"") -> 0 | V24: =IF(AND($R24="Não",$Q24<>"",$Q24<=Hoje+JanelaRet,$Q24>=Hoje-60),MAX($V$4:$V23)+1,"") -> 0
A25: 46211 | B25: 0.625 | C25: Profissional D | D25: P044 | E25: Sessão | F25: Compareceu | H25: 140 | I25: Cartão de débito | J25: =IF($D25="","",IFERROR(INDEX(PacNome,MATCH($D25,PacCod,0)),"Paciente não cadastrado")) -> Paciente 044 | K25: =IF($D25="","",IFERROR(INDEX(PacConv,MATCH($D25,PacCod,0))&"","")) -> Particular | L25: =IF($A25="","",CHOOSE(WEEKDAY($A25,2),"Seg","Ter","Qua","Qui","Sex","Sáb","Dom")) -> Qua | M25: =IF($E25="","",IF($G25<>"",$G25,IFERROR(INDEX(ProcValor,MATCH($E25,ProcNome,0)),0))) -> 140 | N25: =IF($M25="","",IF($F25="Compareceu",$M25,0)) -> 140 | O25: =IF($M25="","",IF($F25="Faltou",$M25,0)) -> 0 | P25: =IF($M25="","",IF($F25="Compareceu",MAX(0,$M25-N($H25)),0)) -> 0 | Q25: =IF(AND($F25="Compareceu",$E25<>"",$A25<>""),IF(IFERROR(INDEX(ProcRet,MATCH($E25,ProcNome,0)),0)>0,$A25+INDEX(ProcRet,MATCH($E25,ProcNome,0)),""),"") -> 46218 | R25: =IF($Q25="","",IF(COUNTIFS(AgPac,$D25,AgData,">"&$A25,AgStatus,"<>Cancelado",AgStatus,"<>Remarcado")>0,"Sim","Não")) -> Sim | S25: =IF($A25="","",IF(AND($F25="Agendado",$A25-Hoje>=0,$A25-Hoje<=DiasConf),"CONFIRMAR",IF(AND($A25<Hoje,OR($F25="Agendado",$F25="Confirmado")),"Atualizar status",IF(AND($F25="Compareceu",$P25>0.005),"Cobrar",IF($F25="Faltou","Falta: reagendar",""))))) -> 0 | T25: =IF($A25="","",DATE(YEAR($A25),MONTH($A25),1)) -> 46204 | U25: =IF($S25="CONFIRMAR",MAX($U$4:$U24)+1,"") -> 0 | V25: =IF(AND($R25="Não",$Q25<>"",$Q25<=Hoje+JanelaRet,$Q25>=Hoje-60),MAX($V$4:$V24)+1,"") -> 0
A26: 46212 | B26: 0.33333333 | C26: Profissional A | D26: P002 | E26: Avaliação | F26: Compareceu | G26: 72 | H26: 36 | I26: Dinheiro | J26: =IF($D26="","",IFERROR(INDEX(PacNome,MATCH($D26,PacCod,0)),"Paciente não cadastrado")) -> Paciente 002 | K26: =IF($D26="","",IFERROR(INDEX(PacConv,MATCH($D26,PacCod,0))&"","")) -> Convênio A | L26: =IF($A26="","",CHOOSE(WEEKDAY($A26,2),"Seg","Ter","Qua","Qui","Sex","Sáb","Dom")) -> Qui | M26: =IF($E26="","",IF($G26<>"",$G26,IFERROR(INDEX(ProcValor,MATCH($E26,ProcNome,0)),0))) -> 72 | N26: =IF($M26="","",IF($F26="Compareceu",$M26,0)) -> 72 | O26: =IF($M26="","",IF($F26="Faltou",$M26,0)) -> 0 | P26: =IF($M26="","",IF($F26="Compareceu",MAX(0,$M26-N($H26)),0)) -> 36 | Q26: =IF(AND($F26="Compareceu",$E26<>"",$A26<>""),IF(IFERROR(INDEX(ProcRet,MATCH($E26,ProcNome,0)),0)>0,$A26+INDEX(ProcRet,MATCH($E26,ProcNome,0)),""),"") -> 46242 | R26: =IF($Q26="","",IF(COUNTIFS(AgPac,$D26,AgData,">"&$A26,AgStatus,"<>Cancelado",AgStatus,"<>Remarcado")>0,"Sim","Não")) -> Sim | S26: =IF($A26="","",IF(AND($F26="Agendado",$A26-Hoje>=0,$A26-Hoje<=DiasConf),"CONFIRMAR",IF(AND($A26<Hoje,OR($F26="Agendado",$F26="Confirmado")),"Atualizar status",IF(AND($F26="Compareceu",$P26>0.005),"Cobrar",IF($F26="Faltou","Falta: reagendar",""))))) -> Cobrar | T26: =IF($A26="","",DATE(YEAR($A26),MONTH($A26),1)) -> 46204 | U26: =IF($S26="CONFIRMAR",MAX($U$4:$U25)+1,"") -> 0 | V26: =IF(AND($R26="Não",$Q26<>"",$Q26<=Hoje+JanelaRet,$Q26>=Hoje-60),MAX($V$4:$V25)+1,"") -> 0
A27: 46212 | B27: 0.4375 | C27: Profissional A | D27: P036 | E27: Limpeza / manutenção | F27: Compareceu | G27: 108 | H27: 108 | I27: Dinheiro | J27: =IF($D27="","",IFERROR(INDEX(PacNome,MATCH($D27,PacCod,0)),"Paciente não cadastrado")) -> Paciente 036 | K27: =IF($D27="","",IFERROR(INDEX(PacConv,MATCH($D27,PacCod,0))&"","")) -> Convênio B | L27: =IF($A27="","",CHOOSE(WEEKDAY($A27,2),"Seg","Ter","Qua","Qui","Sex","Sáb","Dom")) -> Qui | M27: =IF($E27="","",IF($G27<>"",$G27,IFERROR(INDEX(ProcValor,MATCH($E27,ProcNome,0)),0))) -> 108 | N27: =IF($M27="","",IF($F27="Compareceu",$M27,0)) -> 108 | O27: =IF($M27="","",IF($F27="Faltou",$M27,0)) -> 0 | P27: =IF($M27="","",IF($F27="Compareceu",MAX(0,$M27-N($H27)),0)) -> 0 | Q27: =IF(AND($F27="Compareceu",$E27<>"",$A27<>""),IF(IFERROR(INDEX(ProcRet,MATCH($E27,ProcNome,0)),0)>0,$A27+INDEX(ProcRet,MATCH($E27,ProcNome,0)),""),"") -> 46392 | R27: =IF($Q27="","",IF(COUNTIFS(AgPac,$D27,AgData,">"&$A27,AgStatus,"<>Cancelado",AgStatus,"<>Remarcado")>0,"Sim","Não")) -> Sim | S27: =IF($A27="","",IF(AND($F27="Agendado",$A27-Hoje>=0,$A27-Hoje<=DiasConf),"CONFIRMAR",IF(AND($A27<Hoje,OR($F27="Agendado",$F27="Confirmado")),"Atualizar status",IF(AND($F27="Compareceu",$P27>0.005),"Cobrar",IF($F27="Faltou","Falta: reagendar",""))))) -> 0 | T27: =IF($A27="","",DATE(YEAR($A27),MONTH($A27),1)) -> 46204 | U27: =IF($S27="CONFIRMAR",MAX($U$4:$U26)+1,"") -> 0 | V27: =IF(AND($R27="Não",$Q27<>"",$Q27<=Hoje+JanelaRet,$Q27>=Hoje-60),MAX($V$4:$V26)+1,"") -> 0
A28: 46212 | B28: 0.52083333 | C28: Profissional A | D28: P032 | E28: Avaliação | F28: Compareceu | G28: 72 | H28: 72 | I28: Dinheiro | J28: =IF($D28="","",IFERROR(INDEX(PacNome,MATCH($D28,PacCod,0)),"Paciente não cadastrado")) -> Paciente 032 | K28: =IF($D28="","",IFERROR(INDEX(PacConv,MATCH($D28,PacCod,0))&"","")) -> Convênio A | L28: =IF($A28="","",CHOOSE(WEEKDAY($A28,2),"Seg","Ter","Qua","Qui","Sex","Sáb","Dom")) -> Qui | M28: =IF($E28="","",IF($G28<>"",$G28,IFERROR(INDEX(ProcValor,MATCH($E28,ProcNome,0)),0))) -> 72 | N28: =IF($M28="","",IF($F28="Compareceu",$M28,0)) -> 72 | O28: =IF($M28="","",IF($F28="Faltou",$M28,0)) -> 0 | P28: =IF($M28="","",IF($F28="Compareceu",MAX(0,$M28-N($H28)),0)) -> 0 | Q28: =IF(AND($F28="Compareceu",$E28<>"",$A28<>""),IF(IFERROR(INDEX(ProcRet,MATCH($E28,ProcNome,0)),0)>0,$A28+INDEX(ProcRet,MATCH($E28,ProcNome,0)),""),"") -> 46242 | R28: =IF($Q28="","",IF(COUNTIFS(AgPac,$D28,AgData,">"&$A28,AgStatus,"<>Cancelado",AgStatus,"<>Remarcado")>0,"Sim","Não")) -> Sim | S28: =IF($A28="","",IF(AND($F28="Agendado",$A28-Hoje>=0,$A28-Hoje<=DiasConf),"CONFIRMAR",IF(AND($A28<Hoje,OR($F28="Agendado",$F28="Confirmado")),"Atualizar status",IF(AND($F28="Compareceu",$P28>0.005),"Cobrar",IF($F28="Faltou","Falta: reagendar",""))))) -> 0 | T28: =IF($A28="","",DATE(YEAR($A28),MONTH($A28),1)) -> 46204 | U28: =IF($S28="CONFIRMAR",MAX($U$4:$U27)+1,"") -> 0 | V28: =IF(AND($R28="Não",$Q28<>"",$Q28<=Hoje+JanelaRet,$Q28>=Hoje-60),MAX($V$4:$V27)+1,"") -> 0
A29: 46212 | B29: 0.54166667 | C29: Profissional D | D29: P002 | E29: Avaliação | F29: Remarcado | J29: =IF($D29="","",IFERROR(INDEX(PacNome,MATCH($D29,PacCod,0)),"Paciente não cadastrado")) -> Paciente 002 | K29: =IF($D29="","",IFERROR(INDEX(PacConv,MATCH($D29,PacCod,0))&"","")) -> Convênio A | L29: =IF($A29="","",CHOOSE(WEEKDAY($A29,2),"Seg","Ter","Qua","Qui","Sex","Sáb","Dom")) -> Qui | M29: =IF($E29="","",IF($G29<>"",$G29,IFERROR(INDEX(ProcValor,MATCH($E29,ProcNome,0)),0))) -> 120 | N29: =IF($M29="","",IF($F29="Compareceu",$M29,0)) -> 0 | O29: =IF($M29="","",IF($F29="Faltou",$M29,0)) -> 0 | P29: =IF($M29="","",IF($F29="Compareceu",MAX(0,$M29-N($H29)),0)) -> 0 | Q29: =IF(AND($F29="Compareceu",$E29<>"",$A29<>""),IF(IFERROR(INDEX(ProcRet,MATCH($E29,ProcNome,0)),0)>0,$A29+INDEX(ProcRet,MATCH($E29,ProcNome,0)),""),"") -> 0 | R29: =IF($Q29="","",IF(COUNTIFS(AgPac,$D29,AgData,">"&$A29,AgStatus,"<>Cancelado",AgStatus,"<>Remarcado")>0,"Sim","Não")) -> 0 | S29: =IF($A29="","",IF(AND($F29="Agendado",$A29-Hoje>=0,$A29-Hoje<=DiasConf),"CONFIRMAR",IF(AND($A29<Hoje,OR($F29="Agendado",$F29="Confirmado")),"Atualizar status",IF(AND($F29="Compareceu",$P29>0.005),"Cobrar",IF($F29="Faltou","Falta: reagendar",""))))) -> 0 | T29: =IF($A29="","",DATE(YEAR($A29),MONTH($A29),1)) -> 46204 | U29: =IF($S29="CONFIRMAR",MAX($U$4:$U28)+1,"") -> 0 | V29: =IF(AND($R29="Não",$Q29<>"",$Q29<=Hoje+JanelaRet,$Q29>=Hoje-60),MAX($V$4:$V28)+1,"") -> 0
A30: 46213 | B30: 0.35416667 | C30: Profissional A | D30: P025 | E30: Limpeza / manutenção | F30: Compareceu | G30: 108 | J30: =IF($D30="","",IFERROR(INDEX(PacNome,MATCH($D30,PacCod,0)),"Paciente não cadastrado")) -> Paciente 025 | K30: =IF($D30="","",IFERROR(INDEX(PacConv,MATCH($D30,PacCod,0))&"","")) -> Convênio A | L30: =IF($A30="","",CHOOSE(WEEKDAY($A30,2),"Seg","Ter","Qua","Qui","Sex","Sáb","Dom")) -> Sex | M30: =IF($E30="","",IF($G30<>"",$G30,IFERROR(INDEX(ProcValor,MATCH($E30,ProcNome,0)),0))) -> 108 | N30: =IF($M30="","",IF($F30="Compareceu",$M30,0)) -> 108 | O30: =IF($M30="","",IF($F30="Faltou",$M30,0)) -> 0 | P30: =IF($M30="","",IF($F30="Compareceu",MAX(0,$M30-N($H30)),0)) -> 108 | Q30: =IF(AND($F30="Compareceu",$E30<>"",$A30<>""),IF(IFERROR(INDEX(ProcRet,MATCH($E30,ProcNome,0)),0)>0,$A30+INDEX(ProcRet,MATCH($E30,ProcNome,0)),""),"") -> 46393 | R30: =IF($Q30="","",IF(COUNTIFS(AgPac,$D30,AgData,">"&$A30,AgStatus,"<>Cancelado",AgStatus,"<>Remarcado")>0,"Sim","Não")) -> Sim | S30: =IF($A30="","",IF(AND($F30="Agendado",$A30-Hoje>=0,$A30-Hoje<=DiasConf),"CONFIRMAR",IF(AND($A30<Hoje,OR($F30="Agendado",$F30="Confirmado")),"Atualizar status",IF(AND($F30="Compareceu",$P30>0.005),"Cobrar",IF($F30="Faltou","Falta: reagendar",""))))) -> Cobrar | T30: =IF($A30="","",DATE(YEAR($A30),MONTH($A30),1)) -> 46204 | U30: =IF($S30="CONFIRMAR",MAX($U$4:$U29)+1,"") -> 0 | V30: =IF(AND($R30="Não",$Q30<>"",$Q30<=Hoje+JanelaRet,$Q30>=Hoje-60),MAX($V$4:$V29)+1,"") -> 0
A31: 46213 | B31: 0.4375 | C31: Profissional D | D31: P035 | E31: Sessão | F31: Compareceu | H31: 140 | I31: Cartão de débito | J31: =IF($D31="","",IFERROR(INDEX(PacNome,MATCH($D31,PacCod,0)),"Paciente não cadastrado")) -> Paciente 035 | K31: =IF($D31="","",IFERROR(INDEX(PacConv,MATCH($D31,PacCod,0))&"","")) -> Particular | L31: =IF($A31="","",CHOOSE(WEEKDAY($A31,2),"Seg","Ter","Qua","Qui","Sex","Sáb","Dom")) -> Sex | M31: =IF($E31="","",IF($G31<>"",$G31,IFERROR(INDEX(ProcValor,MATCH($E31,ProcNome,0)),0))) -> 140 | N31: =IF($M31="","",IF($F31="Compareceu",$M31,0)) -> 140 | O31: =IF($M31="","",IF($F31="Faltou",$M31,0)) -> 0 | P31: =IF($M31="","",IF($F31="Compareceu",MAX(0,$M31-N($H31)),0)) -> 0 | Q31: =IF(AND($F31="Compareceu",$E31<>"",$A31<>""),IF(IFERROR(INDEX(ProcRet,MATCH($E31,ProcNome,0)),0)>0,$A31+INDEX(ProcRet,MATCH($E31,ProcNome,0)),""),"") -> 46220 | R31: =IF($Q31="","",IF(COUNTIFS(AgPac,$D31,AgData,">"&$A31,AgStatus,"<>Cancelado",AgStatus,"<>Remarcado")>0,"Sim","Não")) -> Sim | S31: =IF($A31="","",IF(AND($F31="Agendado",$A31-Hoje>=0,$A31-Hoje<=DiasConf),"CONFIRMAR",IF(AND($A31<Hoje,OR($F31="Agendado",$F31="Confirmado")),"Atualizar status",IF(AND($F31="Compareceu",$P31>0.005),"Cobrar",IF($F31="Faltou","Falta: reagendar",""))))) -> 0 | T31: =IF($A31="","",DATE(YEAR($A31),MONTH($A31),1)) -> 46204 | U31: =IF($S31="CONFIRMAR",MAX($U$4:$U30)+1,"") -> 0 | V31: =IF(AND($R31="Não",$Q31<>"",$Q31<=Hoje+JanelaRet,$Q31>=Hoje-60),MAX($V$4:$V30)+1,"") -> 0
A32: 46213 | B32: 0.47916667 | C32: Profissional C | D32: P027 | E32: Sessão | F32: Compareceu | H32: 140 | I32: Cartão de débito | J32: =IF($D32="","",IFERROR(INDEX(PacNome,MATCH($D32,PacCod,0)),"Paciente não cadastrado")) -> Paciente 027 | K32: =IF($D32="","",IFERROR(INDEX(PacConv,MATCH($D32,PacCod,0))&"","")) -> Particular | L32: =IF($A32="","",CHOOSE(WEEKDAY($A32,2),"Seg","Ter","Qua","Qui","Sex","Sáb","Dom")) -> Sex | M32: =IF($E32="","",IF($G32<>"",$G32,IFERROR(INDEX(ProcValor,MATCH($E32,ProcNome,0)),0))) -> 140 | N32: =IF($M32="","",IF($F32="Compareceu",$M32,0)) -> 140 | O32: =IF($M32="","",IF($F32="Faltou",$M32,0)) -> 0 | P32: =IF($M32="","",IF($F32="Compareceu",MAX(0,$M32-N($H32)),0)) -> 0 | Q32: =IF(AND($F32="Compareceu",$E32<>"",$A32<>""),IF(IFERROR(INDEX(ProcRet,MATCH($E32,ProcNome,0)),0)>0,$A32+INDEX(ProcRet,MATCH($E32,ProcNome,0)),""),"") -> 46220 | R32: =IF($Q32="","",IF(COUNTIFS(AgPac,$D32,AgData,">"&$A32,AgStatus,"<>Cancelado",AgStatus,"<>Remarcado")>0,"Sim","Não")) -> Sim | S32: =IF($A32="","",IF(AND($F32="Agendado",$A32-Hoje>=0,$A32-Hoje<=DiasConf),"CONFIRMAR",IF(AND($A32<Hoje,OR($F32="Agendado",$F32="Confirmado")),"Atualizar status",IF(AND($F32="Compareceu",$P32>0.005),"Cobrar",IF($F32="Faltou","Falta: reagendar",""))))) -> 0 | T32: =IF($A32="","",DATE(YEAR($A32),MONTH($A32),1)) -> 46204 | U32: =IF($S32="CONFIRMAR",MAX($U$4:$U31)+1,"") -> 0 | V32: =IF(AND($R32="Não",$Q32<>"",$Q32<=Hoje+JanelaRet,$Q32>=Hoje-60),MAX($V$4:$V31)+1,"") -> 0
A33: 46213 | B33: 0.625 | C33: Profissional B | D33: P010 | E33: Sessão | F33: Compareceu | H33: 140 | I33: Dinheiro | J33: =IF($D33="","",IFERROR(INDEX(PacNome,MATCH($D33,PacCod,0)),"Paciente não cadastrado")) -> Paciente 010 | K33: =IF($D33="","",IFERROR(INDEX(PacConv,MATCH($D33,PacCod,0))&"","")) -> Particular | L33: =IF($A33="","",CHOOSE(WEEKDAY($A33,2),"Seg","Ter","Qua","Qui","Sex","Sáb","Dom")) -> Sex | M33: =IF($E33="","",IF($G33<>"",$G33,IFERROR(INDEX(ProcValor,MATCH($E33,ProcNome,0)),0))) -> 140 | N33: =IF($M33="","",IF($F33="Compareceu",$M33,0)) -> 140 | O33: =IF($M33="","",IF($F33="Faltou",$M33,0)) -> 0 | P33: =IF($M33="","",IF($F33="Compareceu",MAX(0,$M33-N($H33)),0)) -> 0 | Q33: =IF(AND($F33="Compareceu",$E33<>"",$A33<>""),IF(IFERROR(INDEX(ProcRet,MATCH($E33,ProcNome,0)),0)>0,$A33+INDEX(ProcRet,MATCH($E33,ProcNome,0)),""),"") -> 46220 | R33: =IF($Q33="","",IF(COUNTIFS(AgPac,$D33,AgData,">"&$A33,AgStatus,"<>Cancelado",AgStatus,"<>Remarcado")>0,"Sim","Não")) -> Sim | S33: =IF($A33="","",IF(AND($F33="Agendado",$A33-Hoje>=0,$A33-Hoje<=DiasConf),"CONFIRMAR",IF(AND($A33<Hoje,OR($F33="Agendado",$F33="Confirmado")),"Atualizar status",IF(AND($F33="Compareceu",$P33>0.005),"Cobrar",IF($F33="Faltou","Falta: reagendar",""))))) -> 0 | T33: =IF($A33="","",DATE(YEAR($A33),MONTH($A33),1)) -> 46204 | U33: =IF($S33="CONFIRMAR",MAX($U$4:$U32)+1,"") -> 0 | V33: =IF(AND($R33="Não",$Q33<>"",$Q33<=Hoje+JanelaRet,$Q33>=Hoje-60),MAX($V$4:$V32)+1,"") -> 0
A34: 46214 | B34: 0.375 | C34: Profissional A | D34: P028 | E34: Sessão | F34: Compareceu | G34: 84 | H34: 84 | I34: Cartão de débito | J34: =IF($D34="","",IFERROR(INDEX(PacNome,MATCH($D34,PacCod,0)),"Paciente não cadastrado")) -> Paciente 028 | K34: =IF($D34="","",IFERROR(INDEX(PacConv,MATCH($D34,PacCod,0))&"","")) -> Convênio B | L34: =IF($A34="","",CHOOSE(WEEKDAY($A34,2),"Seg","Ter","Qua","Qui","Sex","Sáb","Dom")) -> Sáb | M34: =IF($E34="","",IF($G34<>"",$G34,IFERROR(INDEX(ProcValor,MATCH($E34,ProcNome,0)),0))) -> 84 | N34: =IF($M34="","",IF($F34="Compareceu",$M34,0)) -> 84 | O34: =IF($M34="","",IF($F34="Faltou",$M34,0)) -> 0 | P34: =IF($M34="","",IF($F34="Compareceu",MAX(0,$M34-N($H34)),0)) -> 0 | Q34: =IF(AND($F34="Compareceu",$E34<>"",$A34<>""),IF(IFERROR(INDEX(ProcRet,MATCH($E34,ProcNome,0)),0)>0,$A34+INDEX(ProcRet,MATCH($E34,ProcNome,0)),""),"") -> 46221 | R34: =IF($Q34="","",IF(COUNTIFS(AgPac,$D34,AgData,">"&$A34,AgStatus,"<>Cancelado",AgStatus,"<>Remarcado")>0,"Sim","Não")) -> Sim | S34: =IF($A34="","",IF(AND($F34="Agendado",$A34-Hoje>=0,$A34-Hoje<=DiasConf),"CONFIRMAR",IF(AND($A34<Hoje,OR($F34="Agendado",$F34="Confirmado")),"Atualizar status",IF(AND($F34="Compareceu",$P34>0.005),"Cobrar",IF($F34="Faltou","Falta: reagendar",""))))) -> 0 | T34: =IF($A34="","",DATE(YEAR($A34),MONTH($A34),1)) -> 46204 | U34: =IF($S34="CONFIRMAR",MAX($U$4:$U33)+1,"") -> 0 | V34: =IF(AND($R34="Não",$Q34<>"",$Q34<=Hoje+JanelaRet,$Q34>=Hoje-60),MAX($V$4:$V33)+1,"") -> 0
A35: 46214 | B35: 0.60416667 | C35: Profissional D | D35: P007 | E35: Consulta inicial | F35: Compareceu | H35: 250 | I35: Pix | J35: =IF($D35="","",IFERROR(INDEX(PacNome,MATCH($D35,PacCod,0)),"Paciente não cadastrado")) -> Paciente 007 | K35: =IF($D35="","",IFERROR(INDEX(PacConv,MATCH($D35,PacCod,0))&"","")) -> Particular | L35: =IF($A35="","",CHOOSE(WEEKDAY($A35,2),"Seg","Ter","Qua","Qui","Sex","Sáb","Dom")) -> Sáb | M35: =IF($E35="","",IF($G35<>"",$G35,IFERROR(INDEX(ProcValor,MATCH($E35,ProcNome,0)),0))) -> 250 | N35: =IF($M35="","",IF($F35="Compareceu",$M35,0)) -> 250 | O35: =IF($M35="","",IF($F35="Faltou",$M35,0)) -> 0 | P35: =IF($M35="","",IF($F35="Compareceu",MAX(0,$M35-N($H35)),0)) -> 0 | Q35: =IF(AND($F35="Compareceu",$E35<>"",$A35<>""),IF(IFERROR(INDEX(ProcRet,MATCH($E35,ProcNome,0)),0)>0,$A35+INDEX(ProcRet,MATCH($E35,ProcNome,0)),""),"") -> 0 | R35: =IF($Q35="","",IF(COUNTIFS(AgPac,$D35,AgData,">"&$A35,AgStatus,"<>Cancelado",AgStatus,"<>Remarcado")>0,"Sim","Não")) -> 0 | S35: =IF($A35="","",IF(AND($F35="Agendado",$A35-Hoje>=0,$A35-Hoje<=DiasConf),"CONFIRMAR",IF(AND($A35<Hoje,OR($F35="Agendado",$F35="Confirmado")),"Atualizar status",IF(AND($F35="Compareceu",$P35>0.005),"Cobrar",IF($F35="Faltou","Falta: reagendar",""))))) -> 0 | T35: =IF($A35="","",DATE(YEAR($A35),MONTH($A35),1)) -> 46204 | U35: =IF($S35="CONFIRMAR",MAX($U$4:$U34)+1,"") -> 0 | V35: =IF(AND($R35="Não",$Q35<>"",$Q35<=Hoje+JanelaRet,$Q35>=Hoje-60),MAX($V$4:$V34)+1,"") -> 0
A36: 46216 | B36: 0.47916667 | C36: Profissional A | D36: P024 | E36: Consulta inicial | F36: Remarcado | J36: =IF($D36="","",IFERROR(INDEX(PacNome,MATCH($D36,PacCod,0)),"Paciente não cadastrado")) -> Paciente 024 | K36: =IF($D36="","",IFERROR(INDEX(PacConv,MATCH($D36,PacCod,0))&"","")) -> Particular | L36: =IF($A36="","",CHOOSE(WEEKDAY($A36,2),"Seg","Ter","Qua","Qui","Sex","Sáb","Dom")) -> Seg | M36: =IF($E36="","",IF($G36<>"",$G36,IFERROR(INDEX(ProcValor,MATCH($E36,ProcNome,0)),0))) -> 250 | N36: =IF($M36="","",IF($F36="Compareceu",$M36,0)) -> 0 | O36: =IF($M36="","",IF($F36="Faltou",$M36,0)) -> 0 | P36: =IF($M36="","",IF($F36="Compareceu",MAX(0,$M36-N($H36)),0)) -> 0 | Q36: =IF(AND($F36="Compareceu",$E36<>"",$A36<>""),IF(IFERROR(INDEX(ProcRet,MATCH($E36,ProcNome,0)),0)>0,$A36+INDEX(ProcRet,MATCH($E36,ProcNome,0)),""),"") -> 0 | R36: =IF($Q36="","",IF(COUNTIFS(AgPac,$D36,AgData,">"&$A36,AgStatus,"<>Cancelado",AgStatus,"<>Remarcado")>0,"Sim","Não")) -> 0 | S36: =IF($A36="","",IF(AND($F36="Agendado",$A36-Hoje>=0,$A36-Hoje<=DiasConf),"CONFIRMAR",IF(AND($A36<Hoje,OR($F36="Agendado",$F36="Confirmado")),"Atualizar status",IF(AND($F36="Compareceu",$P36>0.005),"Cobrar",IF($F36="Faltou","Falta: reagendar",""))))) -> 0 | T36: =IF($A36="","",DATE(YEAR($A36),MONTH($A36),1)) -> 46204 | U36: =IF($S36="CONFIRMAR",MAX($U$4:$U35)+1,"") -> 0 | V36: =IF(AND($R36="Não",$Q36<>"",$Q36<=Hoje+JanelaRet,$Q36>=Hoje-60),MAX($V$4:$V35)+1,"") -> 0
