Workbook
Name Categorias: Config!$E$5:$E$34
Name CorteA: Config!$C$9
Name CorteB: Config!$C$10
Name DiasAn: Config!$C$6
Name DiasParado: Config!$C$7
Name FatMax: Config!$C$8
Name Fornecedores: Config!$G$5:$G$34
Name Hoje: Config!$C$5
Name MovCod: 'Movimentações'!$B$5:$B$3004
Name MovData: 'Movimentações'!$A$5:$A$3004
Name MovQtd: 'Movimentações'!$D$5:$D$3004
Name MovTipo: 'Movimentações'!$C$5:$C$3004
Name ProdCod: Produtos!$A$5:$A$304
Name ProdCusto: Produtos!$F$5:$F$304
Name ProdNome: Produtos!$B$5:$B$304
Name Unidades: Config!$F$5:$F$34

Sheet Início
A1: Estoque Inteligente com Curva ABC
A2: Carvex XLS · Nunca mais falte o que vende, nunca mais sobre o que não vende
B4: ESTE É O ARQUIVO DE EXEMPLO: todos os dados são fictícios. Use-o para entender como a planilha funciona e comece a sua pela PLANILHA-LIMPA.xlsx.
B6: O que esta planilha faz
B7: Registre as entradas e saídas e a planilha calcula o estoque atual de cada item, avisa o que precisa repor, o que está em excesso, o que está parado, monta a lista de compras e classifica seus produtos na Curva ABC (o que realmente paga as contas).
B9: Como começar (5 minutos)
B10: 1. Config | C10: Informe os períodos de análise (padrão: 90 dias), o fator de estoque máximo e os cortes da Curva ABC. Cadastre fornecedores e categorias.
B11: 2. Cadastre os produtos | C11: Em Produtos: código único, nome, custo, preço de venda, estoque inicial (contagem de hoje) e estoque mínimo.
B12: 3. Lance as movimentações | C12: Em Movimentações: data, código, Entrada ou Saída e quantidade. Compras e devoluções de venda = Entrada; vendas e perdas = Saída.
B13: 4. Veja a Posição | C13: Na aba Posição, o Status mostra RUPTURA, REPOR, OK ou EXCESSO de cada item, e se está Parado.
B14: 5. Use a lista de compras | C14: Na aba Compras, veja o que comprar, de qual fornecedor e quanto vai custar.
B16: Mapa das abas (clique para ir)
B17: Config | C17: Parâmetros gerais, categorias, unidades e fornecedores.
B18: Produtos | C18: Cadastro (até 300 itens).
B19: Movimentações | C19: Todas as entradas e saídas (até 3.000 linhas).
B20: Posição | C20: Estoque atual, status, cobertura, itens parados e sugestão de compra.
B21: Curva ABC | C21: Ranking automático por faturamento e classes A/B/C com gráfico de Pareto.
B22: Compras | C22: Lista de compras pronta com valores por fornecedor.
B23: Dashboard | C23: Indicadores e gráficos.
B25: Legenda de cores
B26: Amarelo | C26: Célula que VOCÊ preenche.
B27: Cinza | C27: Cálculo automático. Não digite aqui.
B28: Verde escuro | C28: Cabeçalho de coluna.
B30: Atenção
B31: • O estoque inicial é a contagem física do dia em que você começou a usar a planilha. Depois disso, só lance movimentações.
B32: • O Código do produto deve ser único e igual nas abas Produtos e Movimentações.
B33: • Para corrigir um erro, edite a linha da movimentação (não crie uma saída para 'desfazer').
B35: Carvex XLS · Estoque Inteligente com Curva ABC · versão 1.0 · Dúvidas: consulte o TUTORIAL.md e o MANUAL.md que acompanham o produto.

Sheet Config
A1: Configurações
A2: Preencha as células amarelas. | H2: EXEMPLO - dados fictícios
B4: Empresa | C4: Papelaria Exemplo | E4: Categorias | F4: Unidades | G4: Fornecedores
B5: Data de hoje (referência) | C5: 46303 | E5: Papelaria | F5: un | G5: Distribuidora Alfa
B6: Período para medir vendas (dias) | C6: 90 | E6: Escritório | F6: cx | G6: Atacado Beta
B7: Dias sem saída para considerar 'Parado' | C7: 90 | E7: Informática | F7: pct | G7: Importadora Gama
B8: Estoque máximo = mínimo x (fator) | C8: 2 | E8: Escolar | F8: kg | G8: Fábrica Delta
B9: Curva ABC: limite da classe A (% acumulado) | C9: 0.8 | E9: Embalagens | F9: L | G9: Papelaria Central
B10: Curva ABC: limite da classe B (% acumulado) | C10: 0.95 | E10: Limpeza | F10: m
E11: Presentes | F11: par
B12: Dica: Estoque máximo (fator 2) = 2 x o mínimo. Acima disso o item aparece como EXCESSO.

Sheet Produtos
A1: Cadastro de produtos
A2: Um produto por linha. O código não pode repetir. | J2: EXEMPLO - dados fictícios
A4: Código | B4: Produto | C4: Categoria | D4: Unidade | E4: Fornecedor principal | F4: Custo unitário (R$) | G4: Preço de venda (R$) | H4: Estoque inicial | I4: Estoque mínimo | J4: Prazo de reposição (dias)
A5: E001 | B5: Caderno universitário 10 matérias | C5: Escolar | D5: un | E5: Papelaria Central | F5: 9.5 | G5: 19.9 | H5: 72 | I5: 36 | J5: 5
A6: E002 | B6: Caneta esferográfica azul (cx 50) | C6: Papelaria | D6: cx | E6: Atacado Beta | F6: 22 | G6: 44.9 | H6: 24 | I6: 12 | J6: 10
A7: E003 | B7: Papel A4 75g (resma) | C7: Escritório | D7: pct | E7: Distribuidora Alfa | F7: 21.5 | G7: 32.9 | H7: 96 | I7: 48 | J7: 3
A8: E004 | B8: Pasta suspensa (pct 25) | C8: Escritório | D8: pct | E8: Distribuidora Alfa | F8: 28 | G8: 54.9 | H8: 6 | I8: 3 | J8: 7
A9: E005 | B9: Grampeador médio | C9: Escritório | D9: un | E9: Fábrica Delta | F9: 14 | G9: 29.9 | H9: 6 | I9: 3 | J9: 5
A10: E006 | B10: Mouse óptico USB | C10: Informática | D10: un | E10: Importadora Gama | F10: 11 | G10: 24.9 | H10: 6 | I10: 3 | J10: 5
A11: E007 | B11: Pen drive 32GB | C11: Informática | D11: un | E11: Importadora Gama | F11: 22 | G11: 44.9 | H11: 20 | I11: 10 | J11: 3
A12: E008 | B12: Cabo USB-C 1m | C12: Informática | D12: un | E12: Importadora Gama | F12: 6.5 | G12: 19.9 | H12: 32 | I12: 16 | J12: 5
A13: E009 | B13: Mochila escolar 20L | C13: Escolar | D13: un | E13: Fábrica Delta | F13: 46 | G13: 99.9 | H13: 12 | I13: 6 | J13: 10
A14: E010 | B14: Estojo duplo | C14: Escolar | D14: un | E14: Papelaria Central | F14: 8.5 | G14: 21.9 | H14: 6 | I14: 3 | J14: 5
A15: E011 | B15: Lápis de cor (cx 24) | C15: Escolar | D15: cx | E15: Papelaria Central | F15: 7.9 | G15: 18.9 | H15: 10 | I15: 5 | J15: 7
A16: E012 | B16: Cola branca 90g | C16: Escolar | D16: un | E16: Atacado Beta | F16: 1.9 | G16: 4.9 | H16: 22 | I16: 11 | J16: 7
... A44: E040 | B44: Porta-retrato 10x15 | C44: Presentes | D44: un | E44: Importadora Gama | F44: 6.2 | G44: 17.9 | H44: 6 | I44: 3 | J44: 3

Sheet Movimentações
A1: Movimentações de estoque
A2: Entrada = compra/devolução de cliente. Saída = venda/perda/consumo. | H2: EXEMPLO - dados fictícios
A4: Data | B4: Código | C4: Tipo | D4: Quantidade | E4: Observação (NF, pedido...) | F4: Produto | G4: Valor (qtd x custo) | H4: Alerta
A5: 46204 | B5: E004 | C5: Saída | D5: 1 | E5: Venda balcão | F5: =IF($B5="","",IFERROR(INDEX(ProdNome,MATCH($B5,ProdCod,0)),"Código não cadastrado")) -> Pasta suspensa (pct 25) | G5: =IF(OR($B5="",$D5=""),"",$D5*IFERROR(INDEX(ProdCusto,MATCH($B5,ProdCod,0)),0)) -> 28 | H5: =IF($A5="","",IF(OR($B5="",$C5="",$D5=""),"Preencher tudo",IF($F5="Código não cadastrado","Código inválido","OK"))) -> OK
A6: 46204 | B6: E005 | C6: Saída | D6: 1 | E6: Venda balcão | F6: =IF($B6="","",IFERROR(INDEX(ProdNome,MATCH($B6,ProdCod,0)),"Código não cadastrado")) -> Grampeador médio | G6: =IF(OR($B6="",$D6=""),"",$D6*IFERROR(INDEX(ProdCusto,MATCH($B6,ProdCod,0)),0)) -> 14 | H6: =IF($A6="","",IF(OR($B6="",$C6="",$D6=""),"Preencher tudo",IF($F6="Código não cadastrado","Código inválido","OK"))) -> OK
A7: 46204 | B7: E006 | C7: Saída | D7: 1 | E7: Venda balcão | F7: =IF($B7="","",IFERROR(INDEX(ProdNome,MATCH($B7,ProdCod,0)),"Código não cadastrado")) -> Mouse óptico USB | G7: =IF(OR($B7="",$D7=""),"",$D7*IFERROR(INDEX(ProdCusto,MATCH($B7,ProdCod,0)),0)) -> 11 | H7: =IF($A7="","",IF(OR($B7="",$C7="",$D7=""),"Preencher tudo",IF($F7="Código não cadastrado","Código inválido","OK"))) -> OK
A8: 46204 | B8: E007 | C8: Saída | D8: 6 | E8: Venda balcão | F8: =IF($B8="","",IFERROR(INDEX(ProdNome,MATCH($B8,ProdCod,0)),"Código não cadastrado")) -> Pen drive 32GB | G8: =IF(OR($B8="",$D8=""),"",$D8*IFERROR(INDEX(ProdCusto,MATCH($B8,ProdCod,0)),0)) -> 132 | H8: =IF($A8="","",IF(OR($B8="",$C8="",$D8=""),"Preencher tudo",IF($F8="Código não cadastrado","Código inválido","OK"))) -> OK
A9: 46204 | B9: E013 | C9: Saída | D9: 6 | E9: Venda balcão | F9: =IF($B9="","",IFERROR(INDEX(ProdNome,MATCH($B9,ProdCod,0)),"Código não cadastrado")) -> Tesoura escolar | G9: =IF(OR($B9="",$D9=""),"",$D9*IFERROR(INDEX(ProdCusto,MATCH($B9,ProdCod,0)),0)) -> 16.8 | H9: =IF($A9="","",IF(OR($B9="",$C9="",$D9=""),"Preencher tudo",IF($F9="Código não cadastrado","Código inválido","OK"))) -> OK
A10: 46204 | B10: E019 | C10: Saída | D10: 3 | E10: Venda balcão | F10: =IF($B10="","",IFERROR(INDEX(ProdNome,MATCH($B10,ProdCod,0)),"Código não cadastrado")) -> Papel toalha (pct 2) | G10: =IF(OR($B10="",$D10=""),"",$D10*IFERROR(INDEX(ProdCusto,MATCH($B10,ProdCod,0)),0)) -> 17.7 | H10: =IF($A10="","",IF(OR($B10="",$C10="",$D10=""),"Preencher tudo",IF($F10="Código não cadastrado","Código inválido","OK"))) -> OK
A11: 46204 | B11: E022 | C11: Saída | D11: 1 | E11: Venda balcão | F11: =IF($B11="","",IFERROR(INDEX(ProdNome,MATCH($B11,ProdCod,0)),"Código não cadastrado")) -> Garrafa squeeze 600ml | G11: =IF(OR($B11="",$D11=""),"",$D11*IFERROR(INDEX(ProdCusto,MATCH($B11,ProdCod,0)),0)) -> 9.9 | H11: =IF($A11="","",IF(OR($B11="",$C11="",$D11=""),"Preencher tudo",IF($F11="Código não cadastrado","Código inválido","OK"))) -> OK
A12: 46204 | B12: E030 | C12: Saída | D12: 1 | E12: Venda balcão | F12: =IF($B12="","",IFERROR(INDEX(ProdNome,MATCH($B12,ProdCod,0)),"Código não cadastrado")) -> Toner genérico preto | G12: =IF(OR($B12="",$D12=""),"",$D12*IFERROR(INDEX(ProdCusto,MATCH($B12,ProdCod,0)),0)) -> 62 | H12: =IF($A12="","",IF(OR($B12="",$C12="",$D12=""),"Preencher tudo",IF($F12="Código não cadastrado","Código inválido","OK"))) -> OK
A13: 46204 | B13: E034 | C13: Saída | D13: 3 | E13: Venda balcão | F13: =IF($B13="","",IFERROR(INDEX(ProdNome,MATCH($B13,ProdCod,0)),"Código não cadastrado")) -> Tinta guache (kit 6) | G13: =IF(OR($B13="",$D13=""),"",$D13*IFERROR(INDEX(ProdCusto,MATCH($B13,ProdCod,0)),0)) -> 26.1 | H13: =IF($A13="","",IF(OR($B13="",$C13="",$D13=""),"Preencher tudo",IF($F13="Código não cadastrado","Código inválido","OK"))) -> OK
A14: 46204 | B14: E035 | C14: Saída | D14: 1 | E14: Venda balcão | F14: =IF($B14="","",IFERROR(INDEX(ProdNome,MATCH($B14,ProdCod,0)),"Código não cadastrado")) -> Papel fotográfico A4 (pct 20) | G14: =IF(OR($B14="",$D14=""),"",$D14*IFERROR(INDEX(ProdCusto,MATCH($B14,ProdCod,0)),0)) -> 12.5 | H14: =IF($A14="","",IF(OR($B14="",$C14="",$D14=""),"Preencher tudo",IF($F14="Código não cadastrado","Código inválido","OK"))) -> OK
A15: 46205 | B15: E009 | C15: Entrada | D15: 6 | E15: NF 5247 | F15: =IF($B15="","",IFERROR(INDEX(ProdNome,MATCH($B15,ProdCod,0)),"Código não cadastrado")) -> Mochila escolar 20L | G15: =IF(OR($B15="",$D15=""),"",$D15*IFERROR(INDEX(ProdCusto,MATCH($B15,ProdCod,0)),0)) -> 276 | H15: =IF($A15="","",IF(OR($B15="",$C15="",$D15=""),"Preencher tudo",IF($F15="Código não cadastrado","Código inválido","OK"))) -> OK
A16: 46205 | B16: E010 | C16: Saída | D16: 2 | E16: Venda balcão | F16: =IF($B16="","",IFERROR(INDEX(ProdNome,MATCH($B16,ProdCod,0)),"Código não cadastrado")) -> Estojo duplo | G16: =IF(OR($B16="",$D16=""),"",$D16*IFERROR(INDEX(ProdCusto,MATCH($B16,ProdCod,0)),0)) -> 17 | H16: =IF($A16="","",IF(OR($B16="",$C16="",$D16=""),"Preencher tudo",IF($F16="Código não cadastrado","Código inválido","OK"))) -> OK
... A698: 46303 | B698: E022 | C698: Saída | D698: 2 | E698: Venda balcão | F698: =IF($B698="","",IFERROR(INDEX(ProdNome,MATCH($B698,ProdCod,0)),"Código não cadastrado")) -> Garrafa squeeze 600ml | G698: =IF(OR($B698="",$D698=""),"",$D698*IFERROR(INDEX(ProdCusto,MATCH($B698,ProdCod,0)),0)) -> 19.8 | H698: =IF($A698="","",IF(OR($B698="",$C698="",$D698=""),"Preencher tudo",IF($F698="Código não cadastrado","Código inválido","OK"))) -> OK
F699: =IF($B699="","",IFERROR(INDEX(ProdNome,MATCH($B699,ProdCod,0)),"Código não cadastrado")) -> 0 | G699: =IF(OR($B699="",$D699=""),"",$D699*IFERROR(INDEX(ProdCusto,MATCH($B699,ProdCod,0)),0)) -> 0 | H699: =IF($A699="","",IF(OR($B699="",$C699="",$D699=""),"Preencher tudo",IF($F699="Código não cadastrado","Código inválido","OK"))) -> 0
F700: =IF($B700="","",IFERROR(INDEX(ProdNome,MATCH($B700,ProdCod,0)),"Código não cadastrado")) -> 0 | G700: =IF(OR($B700="",$D700=""),"",$D700*IFERROR(INDEX(ProdCusto,MATCH($B700,ProdCod,0)),0)) -> 0 | H700: =IF($A700="","",IF(OR($B700="",$C700="",$D700=""),"Preencher tudo",IF($F700="Código não cadastrado","Código inválido","OK"))) -> 0
F701: =IF($B701="","",IFERROR(INDEX(ProdNome,MATCH($B701,ProdCod,0)),"Código não cadastrado")) -> 0 | G701: =IF(OR($B701="",$D701=""),"",$D701*IFERROR(INDEX(ProdCusto,MATCH($B701,ProdCod,0)),0)) -> 0 | H701: =IF($A701="","",IF(OR($B701="",$C701="",$D701=""),"Preencher tudo",IF($F701="Código não cadastrado","Código inválido","OK"))) -> 0
F702: =IF($B702="","",IFERROR(INDEX(ProdNome,MATCH($B702,ProdCod,0)),"Código não cadastrado")) -> 0 | G702: =IF(OR($B702="",$D702=""),"",$D702*IFERROR(INDEX(ProdCusto,MATCH($B702,ProdCod,0)),0)) -> 0 | H702: =IF($A702="","",IF(OR($B702="",$C702="",$D702=""),"Preencher tudo",IF($F702="Código não cadastrado","Código inválido","OK"))) -> 0
F703: =IF($B703="","",IFERROR(INDEX(ProdNome,MATCH($B703,ProdCod,0)),"Código não cadastrado")) -> 0 | G703: =IF(OR($B703="",$D703=""),"",$D703*IFERROR(INDEX(ProdCusto,MATCH($B703,ProdCod,0)),0)) -> 0 | H703: =IF($A703="","",IF(OR($B703="",$C703="",$D703=""),"Preencher tudo",IF($F703="Código não cadastrado","Código inválido","OK"))) -> 0
F704: =IF($B704="","",IFERROR(INDEX(ProdNome,MATCH($B704,ProdCod,0)),"Código não cadastrado")) -> 0 | G704: =IF(OR($B704="",$D704=""),"",$D704*IFERROR(INDEX(ProdCusto,MATCH($B704,ProdCod,0)),0)) -> 0 | H704: =IF($A704="","",IF(OR($B704="",$C704="",$D704=""),"Preencher tudo",IF($F704="Código não cadastrado","Código inválido","OK"))) -> 0
F705: =IF($B705="","",IFERROR(INDEX(ProdNome,MATCH($B705,ProdCod,0)),"Código não cadastrado")) -> 0 | G705: =IF(OR($B705="",$D705=""),"",$D705*IFERROR(INDEX(ProdCusto,MATCH($B705,ProdCod,0)),0)) -> 0 | H705: =IF($A705="","",IF(OR($B705="",$C705="",$D705=""),"Preencher tudo",IF($F705="Código não cadastrado","Código inválido","OK"))) -> 0
F706: =IF($B706="","",IFERROR(INDEX(ProdNome,MATCH($B706,ProdCod,0)),"Código não cadastrado")) -> 0 | G706: =IF(OR($B706="",$D706=""),"",$D706*IFERROR(INDEX(ProdCusto,MATCH($B706,ProdCod,0)),0)) -> 0 | H706: =IF($A706="","",IF(OR($B706="",$C706="",$D706=""),"Preencher tudo",IF($F706="Código não cadastrado","Código inválido","OK"))) -> 0
F707: =IF($B707="","",IFERROR(INDEX(ProdNome,MATCH($B707,ProdCod,0)),"Código não cadastrado")) -> 0 | G707: =IF(OR($B707="",$D707=""),"",$D707*IFERROR(INDEX(ProdCusto,MATCH($B707,ProdCod,0)),0)) -> 0 | H707: =IF($A707="","",IF(OR($B707="",$C707="",$D707=""),"Preencher tudo",IF($F707="Código não cadastrado","Código inválido","OK"))) -> 0
F708: =IF($B708="","",IFERROR(INDEX(ProdNome,MATCH($B708,ProdCod,0)),"Código não cadastrado")) -> 0 | G708: =IF(OR($B708="",$D708=""),"",$D708*IFERROR(INDEX(ProdCusto,MATCH($B708,ProdCod,0)),0)) -> 0 | H708: =IF($A708="","",IF(OR($B708="",$C708="",$D708=""),"Preencher tudo",IF($F708="Código não cadastrado","Código inválido","OK"))) -> 0
F709: =IF($B709="","",IFERROR(INDEX(ProdNome,MATCH($B709,ProdCod,0)),"Código não cadastrado")) -> 0 | G709: =IF(OR($B709="",$D709=""),"",$D709*IFERROR(INDEX(ProdCusto,MATCH($B709,ProdCod,0)),0)) -> 0 | H709: =IF($A709="","",IF(OR($B709="",$C709="",$D709=""),"Preencher tudo",IF($F709="Código não cadastrado","Código inválido","OK"))) -> 0
F710: =IF($B710="","",IFERROR(INDEX(ProdNome,MATCH($B710,ProdCod,0)),"Código não cadastrado")) -> 0 | G710: =IF(OR($B710="",$D710=""),"",$D710*IFERROR(INDEX(ProdCusto,MATCH($B710,ProdCod,0)),0)) -> 0 | H710: =IF($A710="","",IF(OR($B710="",$C710="",$D710=""),"Preencher tudo",IF($F710="Código não cadastrado","Código inválido","OK"))) -> 0
... F3004: =IF($B3004="","",IFERROR(INDEX(ProdNome,MATCH($B3004,ProdCod,0)),"Código não cadastrado")) -> 0 | G3004: =IF(OR($B3004="",$D3004=""),"",$D3004*IFERROR(INDEX(ProdCusto,MATCH($B3004,ProdCod,0)),0)) -> 0 | H3004: =IF($A3004="","",IF(OR($B3004="",$C3004="",$D3004=""),"Preencher tudo",IF($F3004="Código não cadastrado","Código inválido","OK"))) -> 0

Sheet Posição
A1: Posição de estoque
A2: Tudo calculado automaticamente. Filtre a coluna Status para ver o que precisa de ação. | X2: EXEMPLO - dados fictícios
A4: Código | B4: Produto | C4: Categoria | D4: Unid. | E4: Estoque inicial | F4: Entradas | G4: Saídas | H4: ESTOQUE ATUAL | I4: Mínimo | J4: Máximo | K4: Custo unit. | L4: Valor em estoque | M4: Saídas no período | N4: Média diária | O4: Cobertura (dias) | P4: Última saída | Q4: STATUS | R4: Parado? | S4: Sugestão de compra (qtd) | T4: Faturamento no período | U4: Chave ABC | V4: Classe ABC | W4: Valor parado | X4: Seq. compra
A5: =IF(Produtos!A5="","",Produtos!A5) -> E001 | B5: =IF($A5="","",Produtos!B5&"") -> Caderno universitário 10 matérias | C5: =IF($A5="","",Produtos!C5&"") -> Escolar | D5: =IF($A5="","",Produtos!D5&"") -> un | E5: =IF($A5="","",N(Produtos!H5)) -> 72 | F5: =IF($A5="","",SUMIFS(MovQtd,MovCod,$A5,MovTipo,"Entrada")) -> 445 | G5: =IF($A5="","",SUMIFS(MovQtd,MovCod,$A5,MovTipo,"Saída")) -> 476 | H5: =IF($A5="","",E5+F5-G5) -> 41 | I5: =IF($A5="","",N(Produtos!I5)) -> 36 | J5: =IF($A5="","",IF(I5>0,ROUNDUP(I5*FatMax,0),"")) -> 72 | K5: =IF($A5="","",N(Produtos!F5)) -> 9.5 | L5: =IF($A5="","",H5*K5) -> 389.5 | M5: =IF($A5="","",SUMIFS(MovQtd,MovCod,$A5,MovTipo,"Saída",MovData,">="&(Hoje-DiasAn),MovData,"<="&Hoje)) -> 452 | N5: =IF($A5="","",M5/DiasAn) -> 5.0222222 | O5: =IF($A5="","",IF(N5>0,H5/N5,"sem giro")) -> 8.1637168 | P5: =IF($A5="","",SUMPRODUCT(MAX((MovCod=$A5)*(MovTipo="Saída")*MovData))) -> 46297 | Q5: =IF($A5="","",IF(H5<=0,"RUPTURA",IF(AND(I5>0,H5<=I5),"REPOR",IF(AND(J5<>"",H5>J5),"EXCESSO","OK")))) -> OK | R5: =IF($A5="","",IF(AND(H5>0,OR(P5=0,Hoje-P5>DiasParado)),"Parado","")) -> 0 | S5: =IF($A5="","",IF(OR(Q5="RUPTURA",Q5="REPOR"),IF(J5="",0,MAX(0,J5-H5)),0)) -> 0 | T5: =IF($A5="","",M5*IF(N(Produtos!G5)>0,Produtos!G5,K5)) -> 8994.8 | U5: =IF($A5="","",IF(T5>0,T5+ROW()/1000000000,"")) -> 8994.8 | V5: =IF($A5="","",IF(U5="","C",INDEX('Curva ABC'!$H$5:$H$304,MATCH(U5,'Curva ABC'!$B$5:$B$304,0)))) -> A | W5: =IF($A5="","",IF(R5="Parado",L5,0)) -> 0 | X5: =IF($A5="","",IF(OR(Q5="RUPTURA",Q5="REPOR"),COUNTIF($Q$5:Q5,"RUPTURA")+COUNTIF($Q$5:Q5,"REPOR"),"")) -> 0
A6: =IF(Produtos!A6="","",Produtos!A6) -> E002 | B6: =IF($A6="","",Produtos!B6&"") -> Caneta esferográfica azul (cx 50) | C6: =IF($A6="","",Produtos!C6&"") -> Papelaria | D6: =IF($A6="","",Produtos!D6&"") -> cx | E6: =IF($A6="","",N(Produtos!H6)) -> 24 | F6: =IF($A6="","",SUMIFS(MovQtd,MovCod,$A6,MovTipo,"Entrada")) -> 146 | G6: =IF($A6="","",SUMIFS(MovQtd,MovCod,$A6,MovTipo,"Saída")) -> 146 | H6: =IF($A6="","",E6+F6-G6) -> 24 | I6: =IF($A6="","",N(Produtos!I6)) -> 12 | J6: =IF($A6="","",IF(I6>0,ROUNDUP(I6*FatMax,0),"")) -> 24 | K6: =IF($A6="","",N(Produtos!F6)) -> 22 | L6: =IF($A6="","",H6*K6) -> 528 | M6: =IF($A6="","",SUMIFS(MovQtd,MovCod,$A6,MovTipo,"Saída",MovData,">="&(Hoje-DiasAn),MovData,"<="&Hoje)) -> 126 | N6: =IF($A6="","",M6/DiasAn) -> 1.4 | O6: =IF($A6="","",IF(N6>0,H6/N6,"sem giro")) -> 17.142857 | P6: =IF($A6="","",SUMPRODUCT(MAX((MovCod=$A6)*(MovTipo="Saída")*MovData))) -> 46298 | Q6: =IF($A6="","",IF(H6<=0,"RUPTURA",IF(AND(I6>0,H6<=I6),"REPOR",IF(AND(J6<>"",H6>J6),"EXCESSO","OK")))) -> OK | R6: =IF($A6="","",IF(AND(H6>0,OR(P6=0,Hoje-P6>DiasParado)),"Parado","")) -> 0 | S6: =IF($A6="","",IF(OR(Q6="RUPTURA",Q6="REPOR"),IF(J6="",0,MAX(0,J6-H6)),0)) -> 0 | T6: =IF($A6="","",M6*IF(N(Produtos!G6)>0,Produtos!G6,K6)) -> 5657.4 | U6: =IF($A6="","",IF(T6>0,T6+ROW()/1000000000,"")) -> 5657.4 | V6: =IF($A6="","",IF(U6="","C",INDEX('Curva ABC'!$H$5:$H$304,MATCH(U6,'Curva ABC'!$B$5:$B$304,0)))) -> A | W6: =IF($A6="","",IF(R6="Parado",L6,0)) -> 0 | X6: =IF($A6="","",IF(OR(Q6="RUPTURA",Q6="REPOR"),COUNTIF($Q$5:Q6,"RUPTURA")+COUNTIF($Q$5:Q6,"REPOR"),"")) -> 0
A7: =IF(Produtos!A7="","",Produtos!A7) -> E003 | B7: =IF($A7="","",Produtos!B7&"") -> Papel A4 75g (resma) | C7: =IF($A7="","",Produtos!C7&"") -> Escritório | D7: =IF($A7="","",Produtos!D7&"") -> pct | E7: =IF($A7="","",N(Produtos!H7)) -> 96 | F7: =IF($A7="","",SUMIFS(MovQtd,MovCod,$A7,MovTipo,"Entrada")) -> 653 | G7: =IF($A7="","",SUMIFS(MovQtd,MovCod,$A7,MovTipo,"Saída")) -> 653 | H7: =IF($A7="","",E7+F7-G7) -> 96 | I7: =IF($A7="","",N(Produtos!I7)) -> 48 | J7: =IF($A7="","",IF(I7>0,ROUNDUP(I7*FatMax,0),"")) -> 96 | K7: =IF($A7="","",N(Produtos!F7)) -> 21.5 | L7: =IF($A7="","",H7*K7) -> 2064 | M7: =IF($A7="","",SUMIFS(MovQtd,MovCod,$A7,MovTipo,"Saída",MovData,">="&(Hoje-DiasAn),MovData,"<="&Hoje)) -> 599 | N7: =IF($A7="","",M7/DiasAn) -> 6.6555556 | O7: =IF($A7="","",IF(N7>0,H7/N7,"sem giro")) -> 14.42404 | P7: =IF($A7="","",SUMPRODUCT(MAX((MovCod=$A7)*(MovTipo="Saída")*MovData))) -> 46295 | Q7: =IF($A7="","",IF(H7<=0,"RUPTURA",IF(AND(I7>0,H7<=I7),"REPOR",IF(AND(J7<>"",H7>J7),"EXCESSO","OK")))) -> OK | R7: =IF($A7="","",IF(AND(H7>0,OR(P7=0,Hoje-P7>DiasParado)),"Parado","")) -> 0 | S7: =IF($A7="","",IF(OR(Q7="RUPTURA",Q7="REPOR"),IF(J7="",0,MAX(0,J7-H7)),0)) -> 0 | T7: =IF($A7="","",M7*IF(N(Produtos!G7)>0,Produtos!G7,K7)) -> 19707.1 | U7: =IF($A7="","",IF(T7>0,T7+ROW()/1000000000,"")) -> 19707.1 | V7: =IF($A7="","",IF(U7="","C",INDEX('Curva ABC'!$H$5:$H$304,MATCH(U7,'Curva ABC'!$B$5:$B$304,0)))) -> A | W7: =IF($A7="","",IF(R7="Parado",L7,0)) -> 0 | X7: =IF($A7="","",IF(OR(Q7="RUPTURA",Q7="REPOR"),COUNTIF($Q$5:Q7,"RUPTURA")+COUNTIF($Q$5:Q7,"REPOR"),"")) -> 0
A8: =IF(Produtos!A8="","",Produtos!A8) -> E004 | B8: =IF($A8="","",Produtos!B8&"") -> Pasta suspensa (pct 25) | C8: =IF($A8="","",Produtos!C8&"") -> Escritório | D8: =IF($A8="","",Produtos!D8&"") -> pct | E8: =IF($A8="","",N(Produtos!H8)) -> 6 | F8: =IF($A8="","",SUMIFS(MovQtd,MovCod,$A8,MovTipo,"Entrada")) -> 12 | G8: =IF($A8="","",SUMIFS(MovQtd,MovCod,$A8,MovTipo,"Saída")) -> 14 | H8: =IF($A8="","",E8+F8-G8) -> 4 | I8: =IF($A8="","",N(Produtos!I8)) -> 3 | J8: =IF($A8="","",IF(I8>0,ROUNDUP(I8*FatMax,0),"")) -> 6 | K8: =IF($A8="","",N(Produtos!F8)) -> 28 | L8: =IF($A8="","",H8*K8) -> 112 | M8: =IF($A8="","",SUMIFS(MovQtd,MovCod,$A8,MovTipo,"Saída",MovData,">="&(Hoje-DiasAn),MovData,"<="&Hoje)) -> 12 | N8: =IF($A8="","",M8/DiasAn) -> 0.13333333 | O8: =IF($A8="","",IF(N8>0,H8/N8,"sem giro")) -> 30 | P8: =IF($A8="","",SUMPRODUCT(MAX((MovCod=$A8)*(MovTipo="Saída")*MovData))) -> 46298 | Q8: =IF($A8="","",IF(H8<=0,"RUPTURA",IF(AND(I8>0,H8<=I8),"REPOR",IF(AND(J8<>"",H8>J8),"EXCESSO","OK")))) -> OK | R8: =IF($A8="","",IF(AND(H8>0,OR(P8=0,Hoje-P8>DiasParado)),"Parado","")) -> 0 | S8: =IF($A8="","",IF(OR(Q8="RUPTURA",Q8="REPOR"),IF(J8="",0,MAX(0,J8-H8)),0)) -> 0 | T8: =IF($A8="","",M8*IF(N(Produtos!G8)>0,Produtos!G8,K8)) -> 658.8 | U8: =IF($A8="","",IF(T8>0,T8+ROW()/1000000000,"")) -> 658.8 | V8: =IF($A8="","",IF(U8="","C",INDEX('Curva ABC'!$H$5:$H$304,MATCH(U8,'Curva ABC'!$B$5:$B$304,0)))) -> B | W8: =IF($A8="","",IF(R8="Parado",L8,0)) -> 0 | X8: =IF($A8="","",IF(OR(Q8="RUPTURA",Q8="REPOR"),COUNTIF($Q$5:Q8,"RUPTURA")+COUNTIF($Q$5:Q8,"REPOR"),"")) -> 0
A9: =IF(Produtos!A9="","",Produtos!A9) -> E005 | B9: =IF($A9="","",Produtos!B9&"") -> Grampeador médio | C9: =IF($A9="","",Produtos!C9&"") -> Escritório | D9: =IF($A9="","",Produtos!D9&"") -> un | E9: =IF($A9="","",N(Produtos!H9)) -> 6 | F9: =IF($A9="","",SUMIFS(MovQtd,MovCod,$A9,MovTipo,"Entrada")) -> 3 | G9: =IF($A9="","",SUMIFS(MovQtd,MovCod,$A9,MovTipo,"Saída")) -> 9 | H9: =IF($A9="","",E9+F9-G9) -> 0 | I9: =IF($A9="","",N(Produtos!I9)) -> 3 | J9: =IF($A9="","",IF(I9>0,ROUNDUP(I9*FatMax,0),"")) -> 6 | K9: =IF($A9="","",N(Produtos!F9)) -> 14 | L9: =IF($A9="","",H9*K9) -> 0 | M9: =IF($A9="","",SUMIFS(MovQtd,MovCod,$A9,MovTipo,"Saída",MovData,">="&(Hoje-DiasAn),MovData,"<="&Hoje)) -> 7 | N9: =IF($A9="","",M9/DiasAn) -> 0.077777778 | O9: =IF($A9="","",IF(N9>0,H9/N9,"sem giro")) -> 0 | P9: =IF($A9="","",SUMPRODUCT(MAX((MovCod=$A9)*(MovTipo="Saída")*MovData))) -> 46262 | Q9: =IF($A9="","",IF(H9<=0,"RUPTURA",IF(AND(I9>0,H9<=I9),"REPOR",IF(AND(J9<>"",H9>J9),"EXCESSO","OK")))) -> RUPTURA | R9: =IF($A9="","",IF(AND(H9>0,OR(P9=0,Hoje-P9>DiasParado)),"Parado","")) -> 0 | S9: =IF($A9="","",IF(OR(Q9="RUPTURA",Q9="REPOR"),IF(J9="",0,MAX(0,J9-H9)),0)) -> 6 | T9: =IF($A9="","",M9*IF(N(Produtos!G9)>0,Produtos!G9,K9)) -> 209.3 | U9: =IF($A9="","",IF(T9>0,T9+ROW()/1000000000,"")) -> 209.3 | V9: =IF($A9="","",IF(U9="","C",INDEX('Curva ABC'!$H$5:$H$304,MATCH(U9,'Curva ABC'!$B$5:$B$304,0)))) -> C | W9: =IF($A9="","",IF(R9="Parado",L9,0)) -> 0 | X9: =IF($A9="","",IF(OR(Q9="RUPTURA",Q9="REPOR"),COUNTIF($Q$5:Q9,"RUPTURA")+COUNTIF($Q$5:Q9,"REPOR"),"")) -> 1
A10: =IF(Produtos!A10="","",Produtos!A10) -> E006 | B10: =IF($A10="","",Produtos!B10&"") -> Mouse óptico USB | C10: =IF($A10="","",Produtos!C10&"") -> Informática | D10: =IF($A10="","",Produtos!D10&"") -> un | E10: =IF($A10="","",N(Produtos!H10)) -> 6 | F10: =IF($A10="","",SUMIFS(MovQtd,MovCod,$A10,MovTipo,"Entrada")) -> 25 | G10: =IF($A10="","",SUMIFS(MovQtd,MovCod,$A10,MovTipo,"Saída")) -> 26 | H10: =IF($A10="","",E10+F10-G10) -> 5 | I10: =IF($A10="","",N(Produtos!I10)) -> 3 | J10: =IF($A10="","",IF(I10>0,ROUNDUP(I10*FatMax,0),"")) -> 6 | K10: =IF($A10="","",N(Produtos!F10)) -> 11 | L10: =IF($A10="","",H10*K10) -> 55 | M10: =IF($A10="","",SUMIFS(MovQtd,MovCod,$A10,MovTipo,"Saída",MovData,">="&(Hoje-DiasAn),MovData,"<="&Hoje)) -> 25 | N10: =IF($A10="","",M10/DiasAn) -> 0.27777778 | O10: =IF($A10="","",IF(N10>0,H10/N10,"sem giro")) -> 18 | P10: =IF($A10="","",SUMPRODUCT(MAX((MovCod=$A10)*(MovTipo="Saída")*MovData))) -> 46303 | Q10: =IF($A10="","",IF(H10<=0,"RUPTURA",IF(AND(I10>0,H10<=I10),"REPOR",IF(AND(J10<>"",H10>J10),"EXCESSO","OK")))) -> OK | R10: =IF($A10="","",IF(AND(H10>0,OR(P10=0,Hoje-P10>DiasParado)),"Parado","")) -> 0 | S10: =IF($A10="","",IF(OR(Q10="RUPTURA",Q10="REPOR"),IF(J10="",0,MAX(0,J10-H10)),0)) -> 0 | T10: =IF($A10="","",M10*IF(N(Produtos!G10)>0,Produtos!G10,K10)) -> 622.5 | U10: =IF($A10="","",IF(T10>0,T10+ROW()/1000000000,"")) -> 622.5 | V10: =IF($A10="","",IF(U10="","C",INDEX('Curva ABC'!$H$5:$H$304,MATCH(U10,'Curva ABC'!$B$5:$B$304,0)))) -> B | W10: =IF($A10="","",IF(R10="Parado",L10,0)) -> 0 | X10: =IF($A10="","",IF(OR(Q10="RUPTURA",Q10="REPOR"),COUNTIF($Q$5:Q10,"RUPTURA")+COUNTIF($Q$5:Q10,"REPOR"),"")) -> 0
A11: =IF(Produtos!A11="","",Produtos!A11) -> E007 | B11: =IF($A11="","",Produtos!B11&"") -> Pen drive 32GB | C11: =IF($A11="","",Produtos!C11&"") -> Informática | D11: =IF($A11="","",Produtos!D11&"") -> un | E11: =IF($A11="","",N(Produtos!H11)) -> 20 | F11: =IF($A11="","",SUMIFS(MovQtd,MovCod,$A11,MovTipo,"Entrada")) -> 107 | G11: =IF($A11="","",SUMIFS(MovQtd,MovCod,$A11,MovTipo,"Saída")) -> 107 | H11: =IF($A11="","",E11+F11-G11) -> 20 | I11: =IF($A11="","",N(Produtos!I11)) -> 10 | J11: =IF($A11="","",IF(I11>0,ROUNDUP(I11*FatMax,0),"")) -> 20 | K11: =IF($A11="","",N(Produtos!F11)) -> 22 | L11: =IF($A11="","",H11*K11) -> 440 | M11: =IF($A11="","",SUMIFS(MovQtd,MovCod,$A11,MovTipo,"Saída",MovData,">="&(Hoje-DiasAn),MovData,"<="&Hoje)) -> 101 | N11: =IF($A11="","",M11/DiasAn) -> 1.1222222 | O11: =IF($A11="","",IF(N11>0,H11/N11,"sem giro")) -> 17.821782 | P11: =IF($A11="","",SUMPRODUCT(MAX((MovCod=$A11)*(MovTipo="Saída")*MovData))) -> 46298 | Q11: =IF($A11="","",IF(H11<=0,"RUPTURA",IF(AND(I11>0,H11<=I11),"REPOR",IF(AND(J11<>"",H11>J11),"EXCESSO","OK")))) -> OK | R11: =IF($A11="","",IF(AND(H11>0,OR(P11=0,Hoje-P11>DiasParado)),"Parado","")) -> 0 | S11: =IF($A11="","",IF(OR(Q11="RUPTURA",Q11="REPOR"),IF(J11="",0,MAX(0,J11-H11)),0)) -> 0 | T11: =IF($A11="","",M11*IF(N(Produtos!G11)>0,Produtos!G11,K11)) -> 4534.9 | U11: =IF($A11="","",IF(T11>0,T11+ROW()/1000000000,"")) -> 4534.9 | V11: =IF($A11="","",IF(U11="","C",INDEX('Curva ABC'!$H$5:$H$304,MATCH(U11,'Curva ABC'!$B$5:$B$304,0)))) -> A | W11: =IF($A11="","",IF(R11="Parado",L11,0)) -> 0 | X11: =IF($A11="","",IF(OR(Q11="RUPTURA",Q11="REPOR"),COUNTIF($Q$5:Q11,"RUPTURA")+COUNTIF($Q$5:Q11,"REPOR"),"")) -> 0
A12: =IF(Produtos!A12="","",Produtos!A12) -> E008 | B12: =IF($A12="","",Produtos!B12&"") -> Cabo USB-C 1m | C12: =IF($A12="","",Produtos!C12&"") -> Informática | D12: =IF($A12="","",Produtos!D12&"") -> un | E12: =IF($A12="","",N(Produtos!H12)) -> 32 | F12: =IF($A12="","",SUMIFS(MovQtd,MovCod,$A12,MovTipo,"Entrada")) -> 115 | G12: =IF($A12="","",SUMIFS(MovQtd,MovCod,$A12,MovTipo,"Saída")) -> 147 | H12: =IF($A12="","",E12+F12-G12) -> 0 | I12: =IF($A12="","",N(Produtos!I12)) -> 16 | J12: =IF($A12="","",IF(I12>0,ROUNDUP(I12*FatMax,0),"")) -> 32 | K12: =IF($A12="","",N(Produtos!F12)) -> 6.5 | L12: =IF($A12="","",H12*K12) -> 0 | M12: =IF($A12="","",SUMIFS(MovQtd,MovCod,$A12,MovTipo,"Saída",MovData,">="&(Hoje-DiasAn),MovData,"<="&Hoje)) -> 123 | N12: =IF($A12="","",M12/DiasAn) -> 1.3666667 | O12: =IF($A12="","",IF(N12>0,H12/N12,"sem giro")) -> 0 | P12: =IF($A12="","",SUMPRODUCT(MAX((MovCod=$A12)*(MovTipo="Saída")*MovData))) -> 46281 | Q12: =IF($A12="","",IF(H12<=0,"RUPTURA",IF(AND(I12>0,H12<=I12),"REPOR",IF(AND(J12<>"",H12>J12),"EXCESSO","OK")))) -> RUPTURA | R12: =IF($A12="","",IF(AND(H12>0,OR(P12=0,Hoje-P12>DiasParado)),"Parado","")) -> 0 | S12: =IF($A12="","",IF(OR(Q12="RUPTURA",Q12="REPOR"),IF(J12="",0,MAX(0,J12-H12)),0)) -> 32 | T12: =IF($A12="","",M12*IF(N(Produtos!G12)>0,Produtos!G12,K12)) -> 2447.7 | U12: =IF($A12="","",IF(T12>0,T12+ROW()/1000000000,"")) -> 2447.7 | V12: =IF($A12="","",IF(U12="","C",INDEX('Curva ABC'!$H$5:$H$304,MATCH(U12,'Curva ABC'!$B$5:$B$304,0)))) -> A | W12: =IF($A12="","",IF(R12="Parado",L12,0)) -> 0 | X12: =IF($A12="","",IF(OR(Q12="RUPTURA",Q12="REPOR"),COUNTIF($Q$5:Q12,"RUPTURA")+COUNTIF($Q$5:Q12,"REPOR"),"")) -> 2
A13: =IF(Produtos!A13="","",Produtos!A13) -> E009 | B13: =IF($A13="","",Produtos!B13&"") -> Mochila escolar 20L | C13: =IF($A13="","",Produtos!C13&"") -> Escolar | D13: =IF($A13="","",Produtos!D13&"") -> un | E13: =IF($A13="","",N(Produtos!H13)) -> 12 | F13: =IF($A13="","",SUMIFS(MovQtd,MovCod,$A13,MovTipo,"Entrada")) -> 72 | G13: =IF($A13="","",SUMIFS(MovQtd,MovCod,$A13,MovTipo,"Saída")) -> 77 | H13: =IF($A13="","",E13+F13-G13) -> 7 | I13: =IF($A13="","",N(Produtos!I13)) -> 6 | J13: =IF($A13="","",IF(I13>0,ROUNDUP(I13*FatMax,0),"")) -> 12 | K13: =IF($A13="","",N(Produtos!F13)) -> 46 | L13: =IF($A13="","",H13*K13) -> 322 | M13: =IF($A13="","",SUMIFS(MovQtd,MovCod,$A13,MovTipo,"Saída",MovData,">="&(Hoje-DiasAn),MovData,"<="&Hoje)) -> 71 | N13: =IF($A13="","",M13/DiasAn) -> 0.78888889 | O13: =IF($A13="","",IF(N13>0,H13/N13,"sem giro")) -> 8.8732394 | P13: =IF($A13="","",SUMPRODUCT(MAX((MovCod=$A13)*(MovTipo="Saída")*MovData))) -> 46302 | Q13: =IF($A13="","",IF(H13<=0,"RUPTURA",IF(AND(I13>0,H13<=I13),"REPOR",IF(AND(J13<>"",H13>J13),"EXCESSO","OK")))) -> OK | R13: =IF($A13="","",IF(AND(H13>0,OR(P13=0,Hoje-P13>DiasParado)),"Parado","")) -> 0 | S13: =IF($A13="","",IF(OR(Q13="RUPTURA",Q13="REPOR"),IF(J13="",0,MAX(0,J13-H13)),0)) -> 0 | T13: =IF($A13="","",M13*IF(N(Produtos!G13)>0,Produtos!G13,K13)) -> 7092.9 | U13: =IF($A13="","",IF(T13>0,T13+ROW()/1000000000,"")) -> 7092.9 | V13: =IF($A13="","",IF(U13="","C",INDEX('Curva ABC'!$H$5:$H$304,MATCH(U13,'Curva ABC'!$B$5:$B$304,0)))) -> A | W13: =IF($A13="","",IF(R13="Parado",L13,0)) -> 0 | X13: =IF($A13="","",IF(OR(Q13="RUPTURA",Q13="REPOR"),COUNTIF($Q$5:Q13,"RUPTURA")+COUNTIF($Q$5:Q13,"REPOR"),"")) -> 0
A14: =IF(Produtos!A14="","",Produtos!A14) -> E010 | B14: =IF($A14="","",Produtos!B14&"") -> Estojo duplo | C14: =IF($A14="","",Produtos!C14&"") -> Escolar | D14: =IF($A14="","",Produtos!D14&"") -> un | E14: =IF($A14="","",N(Produtos!H14)) -> 6 | F14: =IF($A14="","",SUMIFS(MovQtd,MovCod,$A14,MovTipo,"Entrada")) -> 29 | G14: =IF($A14="","",SUMIFS(MovQtd,MovCod,$A14,MovTipo,"Saída")) -> 31 | H14: =IF($A14="","",E14+F14-G14) -> 4 | I14: =IF($A14="","",N(Produtos!I14)) -> 3 | J14: =IF($A14="","",IF(I14>0,ROUNDUP(I14*FatMax,0),"")) -> 6 | K14: =IF($A14="","",N(Produtos!F14)) -> 8.5 | L14: =IF($A14="","",H14*K14) -> 34 | M14: =IF($A14="","",SUMIFS(MovQtd,MovCod,$A14,MovTipo,"Saída",MovData,">="&(Hoje-DiasAn),MovData,"<="&Hoje)) -> 29 | N14: =IF($A14="","",M14/DiasAn) -> 0.32222222 | O14: =IF($A14="","",IF(N14>0,H14/N14,"sem giro")) -> 12.413793 | P14: =IF($A14="","",SUMPRODUCT(MAX((MovCod=$A14)*(MovTipo="Saída")*MovData))) -> 46298 | Q14: =IF($A14="","",IF(H14<=0,"RUPTURA",IF(AND(I14>0,H14<=I14),"REPOR",IF(AND(J14<>"",H14>J14),"EXCESSO","OK")))) -> OK | R14: =IF($A14="","",IF(AND(H14>0,OR(P14=0,Hoje-P14>DiasParado)),"Parado","")) -> 0 | S14: =IF($A14="","",IF(OR(Q14="RUPTURA",Q14="REPOR"),IF(J14="",0,MAX(0,J14-H14)),0)) -> 0 | T14: =IF($A14="","",M14*IF(N(Produtos!G14)>0,Produtos!G14,K14)) -> 635.1 | U14: =IF($A14="","",IF(T14>0,T14+ROW()/1000000000,"")) -> 635.1 | V14: =IF($A14="","",IF(U14="","C",INDEX('Curva ABC'!$H$5:$H$304,MATCH(U14,'Curva ABC'!$B$5:$B$304,0)))) -> B | W14: =IF($A14="","",IF(R14="Parado",L14,0)) -> 0 | X14: =IF($A14="","",IF(OR(Q14="RUPTURA",Q14="REPOR"),COUNTIF($Q$5:Q14,"RUPTURA")+COUNTIF($Q$5:Q14,"REPOR"),"")) -> 0
A15: =IF(Produtos!A15="","",Produtos!A15) -> E011 | B15: =IF($A15="","",Produtos!B15&"") -> Lápis de cor (cx 24) | C15: =IF($A15="","",Produtos!C15&"") -> Escolar | D15: =IF($A15="","",Produtos!D15&"") -> cx | E15: =IF($A15="","",N(Produtos!H15)) -> 10 | F15: =IF($A15="","",SUMIFS(MovQtd,MovCod,$A15,MovTipo,"Entrada")) -> 16 | G15: =IF($A15="","",SUMIFS(MovQtd,MovCod,$A15,MovTipo,"Saída")) -> 26 | H15: =IF($A15="","",E15+F15-G15) -> 0 | I15: =IF($A15="","",N(Produtos!I15)) -> 5 | J15: =IF($A15="","",IF(I15>0,ROUNDUP(I15*FatMax,0),"")) -> 10 | K15: =IF($A15="","",N(Produtos!F15)) -> 7.9 | L15: =IF($A15="","",H15*K15) -> 0 | M15: =IF($A15="","",SUMIFS(MovQtd,MovCod,$A15,MovTipo,"Saída",MovData,">="&(Hoje-DiasAn),MovData,"<="&Hoje)) -> 22 | N15: =IF($A15="","",M15/DiasAn) -> 0.24444444 | O15: =IF($A15="","",IF(N15>0,H15/N15,"sem giro")) -> 0 | P15: =IF($A15="","",SUMPRODUCT(MAX((MovCod=$A15)*(MovTipo="Saída")*MovData))) -> 46249 | Q15: =IF($A15="","",IF(H15<=0,"RUPTURA",IF(AND(I15>0,H15<=I15),"REPOR",IF(AND(J15<>"",H15>J15),"EXCESSO","OK")))) -> RUPTURA | R15: =IF($A15="","",IF(AND(H15>0,OR(P15=0,Hoje-P15>DiasParado)),"Parado","")) -> 0 | S15: =IF($A15="","",IF(OR(Q15="RUPTURA",Q15="REPOR"),IF(J15="",0,MAX(0,J15-H15)),0)) -> 10 | T15: =IF($A15="","",M15*IF(N(Produtos!G15)>0,Produtos!G15,K15)) -> 415.8 | U15: =IF($A15="","",IF(T15>0,T15+ROW()/1000000000,"")) -> 415.8 | V15: =IF($A15="","",IF(U15="","C",INDEX('Curva ABC'!$H$5:$H$304,MATCH(U15,'Curva ABC'!$B$5:$B$304,0)))) -> B | W15: =IF($A15="","",IF(R15="Parado",L15,0)) -> 0 | X15: =IF($A15="","",IF(OR(Q15="RUPTURA",Q15="REPOR"),COUNTIF($Q$5:Q15,"RUPTURA")+COUNTIF($Q$5:Q15,"REPOR"),"")) -> 3
A16: =IF(Produtos!A16="","",Produtos!A16) -> E012 | B16: =IF($A16="","",Produtos!B16&"") -> Cola branca 90g | C16: =IF($A16="","",Produtos!C16&"") -> Escolar | D16: =IF($A16="","",Produtos!D16&"") -> un | E16: =IF($A16="","",N(Produtos!H16)) -> 22 | F16: =IF($A16="","",SUMIFS(MovQtd,MovCod,$A16,MovTipo,"Entrada")) -> 115 | G16: =IF($A16="","",SUMIFS(MovQtd,MovCod,$A16,MovTipo,"Saída")) -> 123 | H16: =IF($A16="","",E16+F16-G16) -> 14 | I16: =IF($A16="","",N(Produtos!I16)) -> 11 | J16: =IF($A16="","",IF(I16>0,ROUNDUP(I16*FatMax,0),"")) -> 22 | K16: =IF($A16="","",N(Produtos!F16)) -> 1.9 | L16: =IF($A16="","",H16*K16) -> 26.6 | M16: =IF($A16="","",SUMIFS(MovQtd,MovCod,$A16,MovTipo,"Saída",MovData,">="&(Hoje-DiasAn),MovData,"<="&Hoje)) -> 117 | N16: =IF($A16="","",M16/DiasAn) -> 1.3 | O16: =IF($A16="","",IF(N16>0,H16/N16,"sem giro")) -> 10.769231 | P16: =IF($A16="","",SUMPRODUCT(MAX((MovCod=$A16)*(MovTipo="Saída")*MovData))) -> 46298 | Q16: =IF($A16="","",IF(H16<=0,"RUPTURA",IF(AND(I16>0,H16<=I16),"REPOR",IF(AND(J16<>"",H16>J16),"EXCESSO","OK")))) -> OK | R16: =IF($A16="","",IF(AND(H16>0,OR(P16=0,Hoje-P16>DiasParado)),"Parado","")) -> 0 | S16: =IF($A16="","",IF(OR(Q16="RUPTURA",Q16="REPOR"),IF(J16="",0,MAX(0,J16-H16)),0)) -> 0 | T16: =IF($A16="","",M16*IF(N(Produtos!G16)>0,Produtos!G16,K16)) -> 573.3 | U16: =IF($A16="","",IF(T16>0,T16+ROW()/1000000000,"")) -> 573.3 | V16: =IF($A16="","",IF(U16="","C",INDEX('Curva ABC'!$H$5:$H$304,MATCH(U16,'Curva ABC'!$B$5:$B$304,0)))) -> B | W16: =IF($A16="","",IF(R16="Parado",L16,0)) -> 0 | X16: =IF($A16="","",IF(OR(Q16="RUPTURA",Q16="REPOR"),COUNTIF($Q$5:Q16,"RUPTURA")+COUNTIF($Q$5:Q16,"REPOR"),"")) -> 0
... A304: =IF(Produtos!A304="","",Produtos!A304) -> 0 | B304: =IF($A304="","",Produtos!B304&"") -> 0 | C304: =IF($A304="","",Produtos!C304&"") -> 0 | D304: =IF($A304="","",Produtos!D304&"") -> 0 | E304: =IF($A304="","",N(Produtos!H304)) -> 0 | F304: =IF($A304="","",SUMIFS(MovQtd,MovCod,$A304,MovTipo,"Entrada")) -> 0 | G304: =IF($A304="","",SUMIFS(MovQtd,MovCod,$A304,MovTipo,"Saída")) -> 0 | H304: =IF($A304="","",E304+F304-G304) -> 0 | I304: =IF($A304="","",N(Produtos!I304)) -> 0 | J304: =IF($A304="","",IF(I304>0,ROUNDUP(I304*FatMax,0),"")) -> 0 | K304: =IF($A304="","",N(Produtos!F304)) -> 0 | L304: =IF($A304="","",H304*K304) -> 0 | M304: =IF($A304="","",SUMIFS(MovQtd,MovCod,$A304,MovTipo,"Saída",MovData,">="&(Hoje-DiasAn),MovData,"<="&Hoje)) -> 0 | N304: =IF($A304="","",M304/DiasAn) -> 0 | O304: =IF($A304="","",IF(N304>0,H304/N304,"sem giro")) -> 0 | P304: =IF($A304="","",SUMPRODUCT(MAX((MovCod=$A304)*(MovTipo="Saída")*MovData))) -> 0 | Q304: =IF($A304="","",IF(H304<=0,"RUPTURA",IF(AND(I304>0,H304<=I304),"REPOR",IF(AND(J304<>"",H304>J304),"EXCESSO","OK")))) -> 0 | R304: =IF($A304="","",IF(AND(H304>0,OR(P304=0,Hoje-P304>DiasParado)),"Parado","")) -> 0 | S304: =IF($A304="","",IF(OR(Q304="RUPTURA",Q304="REPOR"),IF(J304="",0,MAX(0,J304-H304)),0)) -> 0 | T304: =IF($A304="","",M304*IF(N(Produtos!G304)>0,Produtos!G304,K304)) -> 0 | U304: =IF($A304="","",IF(T304>0,T304+ROW()/1000000000,"")) -> 0 | V304: =IF($A304="","",IF(U304="","C",INDEX('Curva ABC'!$H$5:$H$304,MATCH(U304,'Curva ABC'!$B$5:$B$304,0)))) -> 0 | W304: =IF($A304="","",IF(R304="Parado",L304,0)) -> 0 | X304: =IF($A304="","",IF(OR(Q304="RUPTURA",Q304="REPOR"),COUNTIF($Q$5:Q304,"RUPTURA")+COUNTIF($Q$5:Q304,"REPOR"),"")) -> 0

Sheet Curva ABC
A1: Curva ABC
A2: Ranking automático pelo faturamento do período (saídas x preço de venda). A = poucos itens que dão a maior parte do dinheiro. | N2: EXEMPLO - dados fictícios
A4: Ranking | B4: Chave | C4: Código | D4: Produto | E4: Faturamento (R$) | F4: % do total | G4: % acumulado | H4: Classe | J4: Resumo por classe
A5: 1 | B5: =IFERROR(LARGE(Posição!$U$5:$U$304,A5),"") -> 19707.1 | C5: =IF(B5="","",INDEX(Posição!$A$5:$A$304,MATCH(B5,Posição!$U$5:$U$304,0))) -> E003 | D5: =IF(B5="","",INDEX(Posição!$B$5:$B$304,MATCH(B5,Posição!$U$5:$U$304,0))) -> Papel A4 75g (resma) | E5: =IF(B5="","",ROUND(B5,2)) -> 19707.1 | F5: =IF(E5="","",E5/SUM($E$5:$E$304)) -> 0.30445362 | G5: =IF(F5="","",SUM($F$5:F5)) -> 0.30445362 | H5: =IF(F5="","",IF(G5-F5<CorteA,"A",IF(G5-F5<CorteB,"B","C"))) -> A | J5: Classe | K5: Itens | L5: % dos itens | M5: % do faturamento
A6: 2 | B6: =IFERROR(LARGE(Posição!$U$5:$U$304,A6),"") -> 8994.8 | C6: =IF(B6="","",INDEX(Posição!$A$5:$A$304,MATCH(B6,Posição!$U$5:$U$304,0))) -> E001 | D6: =IF(B6="","",INDEX(Posição!$B$5:$B$304,MATCH(B6,Posição!$U$5:$U$304,0))) -> Caderno universitário 10 matérias | E6: =IF(B6="","",ROUND(B6,2)) -> 8994.8 | F6: =IF(E6="","",E6/SUM($E$5:$E$304)) -> 0.13896004 | G6: =IF(F6="","",SUM($F$5:F6)) -> 0.44341366 | H6: =IF(F6="","",IF(G6-F6<CorteA,"A",IF(G6-F6<CorteB,"B","C"))) -> A | J6: A | K6: =COUNTIF($H$5:$H$304,J6) -> 10 | L6: =IFERROR(K6/COUNT($E$5:$E$304),0) -> 0.27027027 | M6: =IFERROR(SUMIF($H$5:$H$304,J6,$E$5:$E$304)/SUM($E$5:$E$304),0) -> 0.80058366
A7: 3 | B7: =IFERROR(LARGE(Posição!$U$5:$U$304,A7),"") -> 7092.9 | C7: =IF(B7="","",INDEX(Posição!$A$5:$A$304,MATCH(B7,Posição!$U$5:$U$304,0))) -> E009 | D7: =IF(B7="","",INDEX(Posição!$B$5:$B$304,MATCH(B7,Posição!$U$5:$U$304,0))) -> Mochila escolar 20L | E7: =IF(B7="","",ROUND(B7,2)) -> 7092.9 | F7: =IF(E7="","",E7/SUM($E$5:$E$304)) -> 0.10957772 | G7: =IF(F7="","",SUM($F$5:F7)) -> 0.55299138 | H7: =IF(F7="","",IF(G7-F7<CorteA,"A",IF(G7-F7<CorteB,"B","C"))) -> A | J7: B | K7: =COUNTIF($H$5:$H$304,J7) -> 18 | L7: =IFERROR(K7/COUNT($E$5:$E$304),0) -> 0.48648649 | M7: =IFERROR(SUMIF($H$5:$H$304,J7,$E$5:$E$304)/SUM($E$5:$E$304),0) -> 0.15483382
A8: 4 | B8: =IFERROR(LARGE(Posição!$U$5:$U$304,A8),"") -> 5657.4 | C8: =IF(B8="","",INDEX(Posição!$A$5:$A$304,MATCH(B8,Posição!$U$5:$U$304,0))) -> E002 | D8: =IF(B8="","",INDEX(Posição!$B$5:$B$304,MATCH(B8,Posição!$U$5:$U$304,0))) -> Caneta esferográfica azul (cx 50) | E8: =IF(B8="","",ROUND(B8,2)) -> 5657.4 | F8: =IF(E8="","",E8/SUM($E$5:$E$304)) -> 0.087400779 | G8: =IF(F8="","",SUM($F$5:F8)) -> 0.64039216 | H8: =IF(F8="","",IF(G8-F8<CorteA,"A",IF(G8-F8<CorteB,"B","C"))) -> A | J8: C | K8: =COUNTIF($H$5:$H$304,J8) -> 9 | L8: =IFERROR(K8/COUNT($E$5:$E$304),0) -> 0.24324324 | M8: =IFERROR(SUMIF($H$5:$H$304,J8,$E$5:$E$304)/SUM($E$5:$E$304),0) -> 0.044582524
A9: 5 | B9: =IFERROR(LARGE(Posição!$U$5:$U$304,A9),"") -> 4534.9 | C9: =IF(B9="","",INDEX(Posição!$A$5:$A$304,MATCH(B9,Posição!$U$5:$U$304,0))) -> E007 | D9: =IF(B9="","",INDEX(Posição!$B$5:$B$304,MATCH(B9,Posição!$U$5:$U$304,0))) -> Pen drive 32GB | E9: =IF(B9="","",ROUND(B9,2)) -> 4534.9 | F9: =IF(E9="","",E9/SUM($E$5:$E$304)) -> 0.070059355 | G9: =IF(F9="","",SUM($F$5:F9)) -> 0.71045151 | H9: =IF(F9="","",IF(G9-F9<CorteA,"A",IF(G9-F9<CorteB,"B","C"))) -> A
A10: 6 | B10: =IFERROR(LARGE(Posição!$U$5:$U$304,A10),"") -> 2447.7 | C10: =IF(B10="","",INDEX(Posição!$A$5:$A$304,MATCH(B10,Posição!$U$5:$U$304,0))) -> E008 | D10: =IF(B10="","",INDEX(Posição!$B$5:$B$304,MATCH(B10,Posição!$U$5:$U$304,0))) -> Cabo USB-C 1m | E10: =IF(B10="","",ROUND(B10,2)) -> 2447.7 | F10: =IF(E10="","",E10/SUM($E$5:$E$304)) -> 0.037814347 | G10: =IF(F10="","",SUM($F$5:F10)) -> 0.74826586 | H10: =IF(F10="","",IF(G10-F10<CorteA,"A",IF(G10-F10<CorteB,"B","C"))) -> A | J10: Como ler: itens A merecem estoque de segurança e reposição frequente. Itens C (a maioria) vendem pouco: compre em pequena quantidade e evite estoque parado.
A11: 7 | B11: =IFERROR(LARGE(Posição!$U$5:$U$304,A11),"") -> 1079.1 | C11: =IF(B11="","",INDEX(Posição!$A$5:$A$304,MATCH(B11,Posição!$U$5:$U$304,0))) -> E030 | D11: =IF(B11="","",INDEX(Posição!$B$5:$B$304,MATCH(B11,Posição!$U$5:$U$304,0))) -> Toner genérico preto | E11: =IF(B11="","",ROUND(B11,2)) -> 1079.1 | F11: =IF(E11="","",E11/SUM($E$5:$E$304)) -> 0.016670941 | G11: =IF(F11="","",SUM($F$5:F11)) -> 0.7649368 | H11: =IF(F11="","",IF(G11-F11<CorteA,"A",IF(G11-F11<CorteB,"B","C"))) -> A
A12: 8 | B12: =IFERROR(LARGE(Posição!$U$5:$U$304,A12),"") -> 786.9 | C12: =IF(B12="","",INDEX(Posição!$A$5:$A$304,MATCH(B12,Posição!$U$5:$U$304,0))) -> E021 | D12: =IF(B12="","",INDEX(Posição!$B$5:$B$304,MATCH(B12,Posição!$U$5:$U$304,0))) -> Caneca branca para sublimação | E12: =IF(B12="","",ROUND(B12,2)) -> 786.9 | F12: =IF(E12="","",E12/SUM($E$5:$E$304)) -> 0.012156763 | G12: =IF(F12="","",SUM($F$5:F12)) -> 0.77709356 | H12: =IF(F12="","",IF(G12-F12<CorteA,"A",IF(G12-F12<CorteB,"B","C"))) -> A
A13: 9 | B13: =IFERROR(LARGE(Posição!$U$5:$U$304,A13),"") -> 773.5 | C13: =IF(B13="","",INDEX(Posição!$A$5:$A$304,MATCH(B13,Posição!$U$5:$U$304,0))) -> E019 | D13: =IF(B13="","",INDEX(Posição!$B$5:$B$304,MATCH(B13,Posição!$U$5:$U$304,0))) -> Papel toalha (pct 2) | E13: =IF(B13="","",ROUND(B13,2)) -> 773.5 | F13: =IF(E13="","",E13/SUM($E$5:$E$304)) -> 0.011949748 | G13: =IF(F13="","",SUM($F$5:F13)) -> 0.78904331 | H13: =IF(F13="","",IF(G13-F13<CorteA,"A",IF(G13-F13<CorteB,"B","C"))) -> A
A14: 10 | B14: =IFERROR(LARGE(Posição!$U$5:$U$304,A14),"") -> 747 | C14: =IF(B14="","",INDEX(Posição!$A$5:$A$304,MATCH(B14,Posição!$U$5:$U$304,0))) -> E014 | D14: =IF(B14="","",INDEX(Posição!$B$5:$B$304,MATCH(B14,Posição!$U$5:$U$304,0))) -> Fita adesiva transparente | E14: =IF(B14="","",ROUND(B14,2)) -> 747 | F14: =IF(E14="","",E14/SUM($E$5:$E$304)) -> 0.011540351 | G14: =IF(F14="","",SUM($F$5:F14)) -> 0.80058366 | H14: =IF(F14="","",IF(G14-F14<CorteA,"A",IF(G14-F14<CorteB,"B","C"))) -> A
A15: 11 | B15: =IFERROR(LARGE(Posição!$U$5:$U$304,A15),"") -> 718.8 | C15: =IF(B15="","",INDEX(Posição!$A$5:$A$304,MATCH(B15,Posição!$U$5:$U$304,0))) -> E016 | D15: =IF(B15="","",INDEX(Posição!$B$5:$B$304,MATCH(B15,Posição!$U$5:$U$304,0))) -> Plástico bolha (rolo 50m) | E15: =IF(B15="","",ROUND(B15,2)) -> 718.8 | F15: =IF(E15="","",E15/SUM($E$5:$E$304)) -> 0.011104691 | G15: =IF(F15="","",SUM($F$5:F15)) -> 0.81168835 | H15: =IF(F15="","",IF(G15-F15<CorteA,"A",IF(G15-F15<CorteB,"B","C"))) -> B
A16: 12 | B16: =IFERROR(LARGE(Posição!$U$5:$U$304,A16),"") -> 718.4 | C16: =IF(B16="","",INDEX(Posição!$A$5:$A$304,MATCH(B16,Posição!$U$5:$U$304,0))) -> E027 | D16: =IF(B16="","",INDEX(Posição!$B$5:$B$304,MATCH(B16,Posição!$U$5:$U$304,0))) -> Fichário argolado | E16: =IF(B16="","",ROUND(B16,2)) -> 718.4 | F16: =IF(E16="","",E16/SUM($E$5:$E$304)) -> 0.011098512 | G16: =IF(F16="","",SUM($F$5:F16)) -> 0.82278686 | H16: =IF(F16="","",IF(G16-F16<CorteA,"A",IF(G16-F16<CorteB,"B","C"))) -> B
A17: 13 | B17: =IFERROR(LARGE(Posição!$U$5:$U$304,A17),"") -> 670.6 | C17: =IF(B17="","",INDEX(Posição!$A$5:$A$304,MATCH(B17,Posição!$U$5:$U$304,0))) -> E017 | D17: =IF(B17="","",INDEX(Posição!$B$5:$B$304,MATCH(B17,Posição!$U$5:$U$304,0))) -> Sacola kraft G (pct 50) | E17: =IF(B17="","",ROUND(B17,2)) -> 670.6 | F17: =IF(E17="","",E17/SUM($E$5:$E$304)) -> 0.010360053 | G17: =IF(F17="","",SUM($F$5:F17)) -> 0.83314692 | H17: =IF(F17="","",IF(G17-F17<CorteA,"A",IF(G17-F17<CorteB,"B","C"))) -> B
A18: 14 | B18: =IFERROR(LARGE(Posição!$U$5:$U$304,A18),"") -> 658.8 | C18: =IF(B18="","",INDEX(Posição!$A$5:$A$304,MATCH(B18,Posição!$U$5:$U$304,0))) -> E004 | D18: =IF(B18="","",INDEX(Posição!$B$5:$B$304,MATCH(B18,Posição!$U$5:$U$304,0))) -> Pasta suspensa (pct 25) | E18: =IF(B18="","",ROUND(B18,2)) -> 658.8 | F18: =IF(E18="","",E18/SUM($E$5:$E$304)) -> 0.010177755 | G18: =IF(F18="","",SUM($F$5:F18)) -> 0.84332467 | H18: =IF(F18="","",IF(G18-F18<CorteA,"A",IF(G18-F18<CorteB,"B","C"))) -> B
A19: 15 | B19: =IFERROR(LARGE(Posição!$U$5:$U$304,A19),"") -> 635.1 | C19: =IF(B19="","",INDEX(Posição!$A$5:$A$304,MATCH(B19,Posição!$U$5:$U$304,0))) -> E010 | D19: =IF(B19="","",INDEX(Posição!$B$5:$B$304,MATCH(B19,Posição!$U$5:$U$304,0))) -> Estojo duplo | E19: =IF(B19="","",ROUND(B19,2)) -> 635.1 | F19: =IF(E19="","",E19/SUM($E$5:$E$304)) -> 0.0098116157 | G19: =IF(F19="","",SUM($F$5:F19)) -> 0.85313629 | H19: =IF(F19="","",IF(G19-F19<CorteA,"A",IF(G19-F19<CorteB,"B","C"))) -> B
A20: 16 | B20: =IFERROR(LARGE(Posição!$U$5:$U$304,A20),"") -> 622.5 | C20: =IF(B20="","",INDEX(Posição!$A$5:$A$304,MATCH(B20,Posição!$U$5:$U$304,0))) -> E006 | D20: =IF(B20="","",INDEX(Posição!$B$5:$B$304,MATCH(B20,Posição!$U$5:$U$304,0))) -> Mouse óptico USB | E20: =IF(B20="","",ROUND(B20,2)) -> 622.5 | F20: =IF(E20="","",E20/SUM($E$5:$E$304)) -> 0.0096169592 | G20: =IF(F20="","",SUM($F$5:F20)) -> 0.86275325 | H20: =IF(F20="","",IF(G20-F20<CorteA,"A",IF(G20-F20<CorteB,"B","C"))) -> B
A21: 17 | B21: =IFERROR(LARGE(Posição!$U$5:$U$304,A21),"") -> 600.6 | C21: =IF(B21="","",INDEX(Posição!$A$5:$A$304,MATCH(B21,Posição!$U$5:$U$304,0))) -> E038 | D21: =IF(B21="","",INDEX(Posição!$B$5:$B$304,MATCH(B21,Posição!$U$5:$U$304,0))) -> Caixa organizadora | E21: =IF(B21="","",ROUND(B21,2)) -> 600.6 | F21: =IF(E21="","",E21/SUM($E$5:$E$304)) -> 0.0092786276 | G21: =IF(F21="","",SUM($F$5:F21)) -> 0.87203187 | H21: =IF(F21="","",IF(G21-F21<CorteA,"A",IF(G21-F21<CorteB,"B","C"))) -> B
A22: 18 | B22: =IFERROR(LARGE(Posição!$U$5:$U$304,A22),"") -> 597.6 | C22: =IF(B22="","",INDEX(Posição!$A$5:$A$304,MATCH(B22,Posição!$U$5:$U$304,0))) -> E022 | D22: =IF(B22="","",INDEX(Posição!$B$5:$B$304,MATCH(B22,Posição!$U$5:$U$304,0))) -> Garrafa squeeze 600ml | E22: =IF(B22="","",ROUND(B22,2)) -> 597.6 | F22: =IF(E22="","",E22/SUM($E$5:$E$304)) -> 0.0092322808 | G22: =IF(F22="","",SUM($F$5:F22)) -> 0.88126416 | H22: =IF(F22="","",IF(G22-F22<CorteA,"A",IF(G22-F22<CorteB,"B","C"))) -> B
... A304: 300 | B304: =IFERROR(LARGE(Posição!$U$5:$U$304,A304),"") -> 0 | C304: =IF(B304="","",INDEX(Posição!$A$5:$A$304,MATCH(B304,Posição!$U$5:$U$304,0))) -> 0 | D304: =IF(B304="","",INDEX(Posição!$B$5:$B$304,MATCH(B304,Posição!$U$5:$U$304,0))) -> 0 | E304: =IF(B304="","",ROUND(B304,2)) -> 0 | F304: =IF(E304="","",E304/SUM($E$5:$E$304)) -> 0 | G304: =IF(F304="","",SUM($F$5:F304)) -> 0 | H304: =IF(F304="","",IF(G304-F304<CorteA,"A",IF(G304-F304<CorteB,"B","C"))) -> 0

Sheet Compras
A1: Lista de compras sugerida
A2: Itens em RUPTURA ou REPOR. Quantidade sugerida = estoque máximo - estoque atual. | K2: EXEMPLO - dados fictícios
I3: TOTAL: | J3: =SUM(J5:J84) -> 811.2
A4: # | B4: Código | C4: Produto | D4: Fornecedor | E4: Status | F4: Estoque atual | G4: Mínimo | H4: Comprar (qtd) | I4: Custo unit. | J4: Total (R$) | K4: Prazo (dias)
A5: 1 | B5: =IFERROR(INDEX(Posição!$A$5:$A$304,MATCH($A5,Posição!$X$5:$X$304,0)),"") -> E005 | C5: =IFERROR(INDEX(Posição!$B$5:$B$304,MATCH($A5,Posição!$X$5:$X$304,0)),"") -> Grampeador médio | D5: =IFERROR(INDEX(Produtos!$E$5:$E$304,MATCH($A5,Posição!$X$5:$X$304,0))&"","") -> Fábrica Delta | E5: =IFERROR(INDEX(Posição!$Q$5:$Q$304,MATCH($A5,Posição!$X$5:$X$304,0)),"") -> RUPTURA | F5: =IFERROR(INDEX(Posição!$H$5:$H$304,MATCH($A5,Posição!$X$5:$X$304,0)),"") -> 0 | G5: =IFERROR(INDEX(Posição!$I$5:$I$304,MATCH($A5,Posição!$X$5:$X$304,0)),"") -> 3 | H5: =IFERROR(INDEX(Posição!$S$5:$S$304,MATCH($A5,Posição!$X$5:$X$304,0)),"") -> 6 | I5: =IFERROR(INDEX(Posição!$K$5:$K$304,MATCH($A5,Posição!$X$5:$X$304,0)),"") -> 14 | J5: =IF(OR(H5="",I5=""),"",H5*I5) -> 84 | K5: =IFERROR(N(INDEX(Produtos!$J$5:$J$304,MATCH($A5,Posição!$X$5:$X$304,0))),"") -> 5
A6: 2 | B6: =IFERROR(INDEX(Posição!$A$5:$A$304,MATCH($A6,Posição!$X$5:$X$304,0)),"") -> E008 | C6: =IFERROR(INDEX(Posição!$B$5:$B$304,MATCH($A6,Posição!$X$5:$X$304,0)),"") -> Cabo USB-C 1m | D6: =IFERROR(INDEX(Produtos!$E$5:$E$304,MATCH($A6,Posição!$X$5:$X$304,0))&"","") -> Importadora Gama | E6: =IFERROR(INDEX(Posição!$Q$5:$Q$304,MATCH($A6,Posição!$X$5:$X$304,0)),"") -> RUPTURA | F6: =IFERROR(INDEX(Posição!$H$5:$H$304,MATCH($A6,Posição!$X$5:$X$304,0)),"") -> 0 | G6: =IFERROR(INDEX(Posição!$I$5:$I$304,MATCH($A6,Posição!$X$5:$X$304,0)),"") -> 16 | H6: =IFERROR(INDEX(Posição!$S$5:$S$304,MATCH($A6,Posição!$X$5:$X$304,0)),"") -> 32 | I6: =IFERROR(INDEX(Posição!$K$5:$K$304,MATCH($A6,Posição!$X$5:$X$304,0)),"") -> 6.5 | J6: =IF(OR(H6="",I6=""),"",H6*I6) -> 208 | K6: =IFERROR(N(INDEX(Produtos!$J$5:$J$304,MATCH($A6,Posição!$X$5:$X$304,0))),"") -> 5
A7: 3 | B7: =IFERROR(INDEX(Posição!$A$5:$A$304,MATCH($A7,Posição!$X$5:$X$304,0)),"") -> E011 | C7: =IFERROR(INDEX(Posição!$B$5:$B$304,MATCH($A7,Posição!$X$5:$X$304,0)),"") -> Lápis de cor (cx 24) | D7: =IFERROR(INDEX(Produtos!$E$5:$E$304,MATCH($A7,Posição!$X$5:$X$304,0))&"","") -> Papelaria Central | E7: =IFERROR(INDEX(Posição!$Q$5:$Q$304,MATCH($A7,Posição!$X$5:$X$304,0)),"") -> RUPTURA | F7: =IFERROR(INDEX(Posição!$H$5:$H$304,MATCH($A7,Posição!$X$5:$X$304,0)),"") -> 0 | G7: =IFERROR(INDEX(Posição!$I$5:$I$304,MATCH($A7,Posição!$X$5:$X$304,0)),"") -> 5 | H7: =IFERROR(INDEX(Posição!$S$5:$S$304,MATCH($A7,Posição!$X$5:$X$304,0)),"") -> 10 | I7: =IFERROR(INDEX(Posição!$K$5:$K$304,MATCH($A7,Posição!$X$5:$X$304,0)),"") -> 7.9 | J7: =IF(OR(H7="",I7=""),"",H7*I7) -> 79 | K7: =IFERROR(N(INDEX(Produtos!$J$5:$J$304,MATCH($A7,Posição!$X$5:$X$304,0))),"") -> 7
A8: 4 | B8: =IFERROR(INDEX(Posição!$A$5:$A$304,MATCH($A8,Posição!$X$5:$X$304,0)),"") -> E014 | C8: =IFERROR(INDEX(Posição!$B$5:$B$304,MATCH($A8,Posição!$X$5:$X$304,0)),"") -> Fita adesiva transparente | D8: =IFERROR(INDEX(Produtos!$E$5:$E$304,MATCH($A8,Posição!$X$5:$X$304,0))&"","") -> Distribuidora Alfa | E8: =IFERROR(INDEX(Posição!$Q$5:$Q$304,MATCH($A8,Posição!$X$5:$X$304,0)),"") -> REPOR | F8: =IFERROR(INDEX(Posição!$H$5:$H$304,MATCH($A8,Posição!$X$5:$X$304,0)),"") -> 7 | G8: =IFERROR(INDEX(Posição!$I$5:$I$304,MATCH($A8,Posição!$X$5:$X$304,0)),"") -> 15 | H8: =IFERROR(INDEX(Posição!$S$5:$S$304,MATCH($A8,Posição!$X$5:$X$304,0)),"") -> 23 | I8: =IFERROR(INDEX(Posição!$K$5:$K$304,MATCH($A8,Posição!$X$5:$X$304,0)),"") -> 1.6 | J8: =IF(OR(H8="",I8=""),"",H8*I8) -> 36.8 | K8: =IFERROR(N(INDEX(Produtos!$J$5:$J$304,MATCH($A8,Posição!$X$5:$X$304,0))),"") -> 3
A9: 5 | B9: =IFERROR(INDEX(Posição!$A$5:$A$304,MATCH($A9,Posição!$X$5:$X$304,0)),"") -> E018 | C9: =IFERROR(INDEX(Posição!$B$5:$B$304,MATCH($A9,Posição!$X$5:$X$304,0)),"") -> Álcool 70% 1L | D9: =IFERROR(INDEX(Produtos!$E$5:$E$304,MATCH($A9,Posição!$X$5:$X$304,0))&"","") -> Distribuidora Alfa | E9: =IFERROR(INDEX(Posição!$Q$5:$Q$304,MATCH($A9,Posição!$X$5:$X$304,0)),"") -> RUPTURA | F9: =IFERROR(INDEX(Posição!$H$5:$H$304,MATCH($A9,Posição!$X$5:$X$304,0)),"") -> 0 | G9: =IFERROR(INDEX(Posição!$I$5:$I$304,MATCH($A9,Posição!$X$5:$X$304,0)),"") -> 5 | H9: =IFERROR(INDEX(Posição!$S$5:$S$304,MATCH($A9,Posição!$X$5:$X$304,0)),"") -> 10 | I9: =IFERROR(INDEX(Posição!$K$5:$K$304,MATCH($A9,Posição!$X$5:$X$304,0)),"") -> 6.2 | J9: =IF(OR(H9="",I9=""),"",H9*I9) -> 62 | K9: =IFERROR(N(INDEX(Produtos!$J$5:$J$304,MATCH($A9,Posição!$X$5:$X$304,0))),"") -> 7
A10: 6 | B10: =IFERROR(INDEX(Posição!$A$5:$A$304,MATCH($A10,Posição!$X$5:$X$304,0)),"") -> E019 | C10: =IFERROR(INDEX(Posição!$B$5:$B$304,MATCH($A10,Posição!$X$5:$X$304,0)),"") -> Papel toalha (pct 2) | D10: =IFERROR(INDEX(Produtos!$E$5:$E$304,MATCH($A10,Posição!$X$5:$X$304,0))&"","") -> Distribuidora Alfa | E10: =IFERROR(INDEX(Posição!$Q$5:$Q$304,MATCH($A10,Posição!$X$5:$X$304,0)),"") -> REPOR | F10: =IFERROR(INDEX(Posição!$H$5:$H$304,MATCH($A10,Posição!$X$5:$X$304,0)),"") -> 5 | G10: =IFERROR(INDEX(Posição!$I$5:$I$304,MATCH($A10,Posição!$X$5:$X$304,0)),"") -> 6 | H10: =IFERROR(INDEX(Posição!$S$5:$S$304,MATCH($A10,Posição!$X$5:$X$304,0)),"") -> 7 | I10: =IFERROR(INDEX(Posição!$K$5:$K$304,MATCH($A10,Posição!$X$5:$X$304,0)),"") -> 5.9 | J10: =IF(OR(H10="",I10=""),"",H10*I10) -> 41.3 | K10: =IFERROR(N(INDEX(Produtos!$J$5:$J$304,MATCH($A10,Posição!$X$5:$X$304,0))),"") -> 7
A11: 7 | B11: =IFERROR(INDEX(Posição!$A$5:$A$304,MATCH($A11,Posição!$X$5:$X$304,0)),"") -> E020 | C11: =IFERROR(INDEX(Posição!$B$5:$B$304,MATCH($A11,Posição!$X$5:$X$304,0)),"") -> Pilha AA (cartela 4) | D11: =IFERROR(INDEX(Produtos!$E$5:$E$304,MATCH($A11,Posição!$X$5:$X$304,0))&"","") -> Importadora Gama | E11: =IFERROR(INDEX(Posição!$Q$5:$Q$304,MATCH($A11,Posição!$X$5:$X$304,0)),"") -> RUPTURA | F11: =IFERROR(INDEX(Posição!$H$5:$H$304,MATCH($A11,Posição!$X$5:$X$304,0)),"") -> 0 | G11: =IFERROR(INDEX(Posição!$I$5:$I$304,MATCH($A11,Posição!$X$5:$X$304,0)),"") -> 4 | H11: =IFERROR(INDEX(Posição!$S$5:$S$304,MATCH($A11,Posição!$X$5:$X$304,0)),"") -> 8 | I11: =IFERROR(INDEX(Posição!$K$5:$K$304,MATCH($A11,Posição!$X$5:$X$304,0)),"") -> 7.5 | J11: =IF(OR(H11="",I11=""),"",H11*I11) -> 60 | K11: =IFERROR(N(INDEX(Produtos!$J$5:$J$304,MATCH($A11,Posição!$X$5:$X$304,0))),"") -> 10
A12: 8 | B12: =IFERROR(INDEX(Posição!$A$5:$A$304,MATCH($A12,Posição!$X$5:$X$304,0)),"") -> E023 | C12: =IFERROR(INDEX(Posição!$B$5:$B$304,MATCH($A12,Posição!$X$5:$X$304,0)),"") -> Agenda 2027 | D12: =IFERROR(INDEX(Produtos!$E$5:$E$304,MATCH($A12,Posição!$X$5:$X$304,0))&"","") -> Papelaria Central | E12: =IFERROR(INDEX(Posição!$Q$5:$Q$304,MATCH($A12,Posição!$X$5:$X$304,0)),"") -> REPOR | F12: =IFERROR(INDEX(Posição!$H$5:$H$304,MATCH($A12,Posição!$X$5:$X$304,0)),"") -> 3 | G12: =IFERROR(INDEX(Posição!$I$5:$I$304,MATCH($A12,Posição!$X$5:$X$304,0)),"") -> 3 | H12: =IFERROR(INDEX(Posição!$S$5:$S$304,MATCH($A12,Posição!$X$5:$X$304,0)),"") -> 3 | I12: =IFERROR(INDEX(Posição!$K$5:$K$304,MATCH($A12,Posição!$X$5:$X$304,0)),"") -> 14 | J12: =IF(OR(H12="",I12=""),"",H12*I12) -> 42 | K12: =IFERROR(N(INDEX(Produtos!$J$5:$J$304,MATCH($A12,Posição!$X$5:$X$304,0))),"") -> 7
A13: 9 | B13: =IFERROR(INDEX(Posição!$A$5:$A$304,MATCH($A13,Posição!$X$5:$X$304,0)),"") -> E025 | C13: =IFERROR(INDEX(Posição!$B$5:$B$304,MATCH($A13,Posição!$X$5:$X$304,0)),"") -> Bloco de notas adesivas | D13: =IFERROR(INDEX(Produtos!$E$5:$E$304,MATCH($A13,Posição!$X$5:$X$304,0))&"","") -> Atacado Beta | E13: =IFERROR(INDEX(Posição!$Q$5:$Q$304,MATCH($A13,Posição!$X$5:$X$304,0)),"") -> RUPTURA | F13: =IFERROR(INDEX(Posição!$H$5:$H$304,MATCH($A13,Posição!$X$5:$X$304,0)),"") -> 0 | G13: =IFERROR(INDEX(Posição!$I$5:$I$304,MATCH($A13,Posição!$X$5:$X$304,0)),"") -> 8 | H13: =IFERROR(INDEX(Posição!$S$5:$S$304,MATCH($A13,Posição!$X$5:$X$304,0)),"") -> 16 | I13: =IFERROR(INDEX(Posição!$K$5:$K$304,MATCH($A13,Posição!$X$5:$X$304,0)),"") -> 3.4 | J13: =IF(OR(H13="",I13=""),"",H13*I13) -> 54.4 | K13: =IFERROR(N(INDEX(Produtos!$J$5:$J$304,MATCH($A13,Posição!$X$5:$X$304,0))),"") -> 10
A14: 10 | B14: =IFERROR(INDEX(Posição!$A$5:$A$304,MATCH($A14,Posição!$X$5:$X$304,0)),"") -> E034 | C14: =IFERROR(INDEX(Posição!$B$5:$B$304,MATCH($A14,Posição!$X$5:$X$304,0)),"") -> Tinta guache (kit 6) | D14: =IFERROR(INDEX(Produtos!$E$5:$E$304,MATCH($A14,Posição!$X$5:$X$304,0))&"","") -> Papelaria Central | E14: =IFERROR(INDEX(Posição!$Q$5:$Q$304,MATCH($A14,Posição!$X$5:$X$304,0)),"") -> RUPTURA | F14: =IFERROR(INDEX(Posição!$H$5:$H$304,MATCH($A14,Posição!$X$5:$X$304,0)),"") -> 0 | G14: =IFERROR(INDEX(Posição!$I$5:$I$304,MATCH($A14,Posição!$X$5:$X$304,0)),"") -> 3 | H14: =IFERROR(INDEX(Posição!$S$5:$S$304,MATCH($A14,Posição!$X$5:$X$304,0)),"") -> 6 | I14: =IFERROR(INDEX(Posição!$K$5:$K$304,MATCH($A14,Posição!$X$5:$X$304,0)),"") -> 8.7 | J14: =IF(OR(H14="",I14=""),"",H14*I14) -> 52.2 | K14: =IFERROR(N(INDEX(Produtos!$J$5:$J$304,MATCH($A14,Posição!$X$5:$X$304,0))),"") -> 7
A15: 11 | B15: =IFERROR(INDEX(Posição!$A$5:$A$304,MATCH($A15,Posição!$X$5:$X$304,0)),"") -> E035 | C15: =IFERROR(INDEX(Posição!$B$5:$B$304,MATCH($A15,Posição!$X$5:$X$304,0)),"") -> Papel fotográfico A4 (pct 20) | D15: =IFERROR(INDEX(Produtos!$E$5:$E$304,MATCH($A15,Posição!$X$5:$X$304,0))&"","") -> Importadora Gama | E15: =IFERROR(INDEX(Posição!$Q$5:$Q$304,MATCH($A15,Posição!$X$5:$X$304,0)),"") -> REPOR | F15: =IFERROR(INDEX(Posição!$H$5:$H$304,MATCH($A15,Posição!$X$5:$X$304,0)),"") -> 3 | G15: =IFERROR(INDEX(Posição!$I$5:$I$304,MATCH($A15,Posição!$X$5:$X$304,0)),"") -> 3 | H15: =IFERROR(INDEX(Posição!$S$5:$S$304,MATCH($A15,Posição!$X$5:$X$304,0)),"") -> 3 | I15: =IFERROR(INDEX(Posição!$K$5:$K$304,MATCH($A15,Posição!$X$5:$X$304,0)),"") -> 12.5 | J15: =IF(OR(H15="",I15=""),"",H15*I15) -> 37.5 | K15: =IFERROR(N(INDEX(Produtos!$J$5:$J$304,MATCH($A15,Posição!$X$5:$X$304,0))),"") -> 5
A16: 12 | B16: =IFERROR(INDEX(Posição!$A$5:$A$304,MATCH($A16,Posição!$X$5:$X$304,0)),"") -> E038 | C16: =IFERROR(INDEX(Posição!$B$5:$B$304,MATCH($A16,Posição!$X$5:$X$304,0)),"") -> Caixa organizadora | D16: =IFERROR(INDEX(Produtos!$E$5:$E$304,MATCH($A16,Posição!$X$5:$X$304,0))&"","") -> Fábrica Delta | E16: =IFERROR(INDEX(Posição!$Q$5:$Q$304,MATCH($A16,Posição!$X$5:$X$304,0)),"") -> REPOR | F16: =IFERROR(INDEX(Posição!$H$5:$H$304,MATCH($A16,Posição!$X$5:$X$304,0)),"") -> 3 | G16: =IFERROR(INDEX(Posição!$I$5:$I$304,MATCH($A16,Posição!$X$5:$X$304,0)),"") -> 3 | H16: =IFERROR(INDEX(Posição!$S$5:$S$304,MATCH($A16,Posição!$X$5:$X$304,0)),"") -> 3 | I16: =IFERROR(INDEX(Posição!$K$5:$K$304,MATCH($A16,Posição!$X$5:$X$304,0)),"") -> 18 | J16: =IF(OR(H16="",I16=""),"",H16*I16) -> 54 | K16: =IFERROR(N(INDEX(Produtos!$J$5:$J$304,MATCH($A16,Posição!$X$5:$X$304,0))),"") -> 7
... A84: 80 | B84: =IFERROR(INDEX(Posição!$A$5:$A$304,MATCH($A84,Posição!$X$5:$X$304,0)),"") -> 0 | C84: =IFERROR(INDEX(Posição!$B$5:$B$304,MATCH($A84,Posição!$X$5:$X$304,0)),"") -> 0 | D84: =IFERROR(INDEX(Produtos!$E$5:$E$304,MATCH($A84,Posição!$X$5:$X$304,0))&"","") -> 0 | E84: =IFERROR(INDEX(Posição!$Q$5:$Q$304,MATCH($A84,Posição!$X$5:$X$304,0)),"") -> 0 | F84: =IFERROR(INDEX(Posição!$H$5:$H$304,MATCH($A84,Posição!$X$5:$X$304,0)),"") -> 0 | G84: =IFERROR(INDEX(Posição!$I$5:$I$304,MATCH($A84,Posição!$X$5:$X$304,0)),"") -> 0 | H84: =IFERROR(INDEX(Posição!$S$5:$S$304,MATCH($A84,Posição!$X$5:$X$304,0)),"") -> 0 | I84: =IFERROR(INDEX(Posição!$K$5:$K$304,MATCH($A84,Posição!$X$5:$X$304,0)),"") -> 0 | J84: =IF(OR(H84="",I84=""),"",H84*I84) -> 0 | K84: =IFERROR(N(INDEX(Produtos!$J$5:$J$304,MATCH($A84,Posição!$X$5:$X$304,0))),"") -> 0

Sheet Dashboard
A1: Dashboard de estoque
A2: Visão geral do estoque. Atualiza sozinho. | J2: EXEMPLO - dados fictícios
